Workbook

Sheet S2赛程
B1: steam链接 | C1: 队名 | D1: 胜 | E1: 负 | I1: steam链接 | J1: 队名 | K1: 胜 | L1: 负
B2: https://steamcommunity.com/profiles/76561198148199573/ | C2: 赤夜紫雨（猛虎下山） | F2: W1 | I2: https://steamcommunity.com/profiles/76561198114117906/ | J2: 秋（Unbowed ） | M2: W1 | O2: W1
B3: https://steamcommunity.com/profiles/76561198301936498/ | C3: 大蟑螂（微雨绸缪2.0） | F3: W2 | J3: 兆焱（我冠了） | M3: W2
A4: 大大大 | B4: https://steamcommunity.com/profiles/76561198845853751/ | C4: yuuu（Chu Ni Byo） | F4: W3 | H4: 小小小 | I4: https://steamcommunity.com/profiles/76561198216148128/ | J4: coconut（椰子岛） | M4: W3 | O4: W4
B5: https://steamcommunity.com/profiles/76561198227985060/ | C5: summer（三万匹磁力） | F5: W4 | J5: 尤也（魂里尤猪仙） | M5: W4
B6: https://steamcommunity.com/profiles/76561198114295313/ | C6: 蜡笔大雪（雪批的奇妙冒险） | F6: G | I6: https://steamcommunity.com/profiles/76561198341323392/ | J6: 所念皆星河（神人之家） | M6: G
B7: https://steamcommunity.com/profiles/76561198227985060/ | C7: 雲天河（YYPKW） | F7: G | J7: starling（难民收容所） | M7: G | O7: W2
G8: 小组bo1循环（3.23~3.29）
C9: 对战 | D9: 比赛 | E9: 截图 | J9: 对战 | K9: 比赛 | L9: 截图 | O9: W3
C10: 赤夜紫雨（猛虎下山） VS 大蟑螂（微雨绸缪2.0） | J10: A VS B
C11: 赤夜紫雨（猛虎下山） VS yuuu | J11: A VS C
C12: 赤夜紫雨（猛虎下山） VS summer（三万匹磁力） | J12: A VS D | O12: W3
C13: 赤夜紫雨（猛虎下山） VS 蜡笔大雪（雪批的奇妙冒险） | J13: A VS E
C14: 赤夜紫雨（猛虎下山） VS 雲天河（YYPKW） | J14: A VS F | O14: W2
C15: 大蟑螂（微雨绸缪2.0） VS yuuu | J15: B VS C
C16: 大蟑螂（微雨绸缪2.0） VS summer（三万匹磁力） | J16: B VS D
C17: 大蟑螂（微雨绸缪2.0） VS 蜡笔大雪（雪批的奇妙冒险） | J17: B VS E | O17: W4
C18: 大蟑螂（微雨绸缪2.0） VS 雲天河（YYPKW） | J18: B VS F
C19: yuuu VS summer（三万匹磁力） | J19: C VS D
C20: yuuu VS 蜡笔大雪（雪批的奇妙冒险） | J20: C VS E | O20: W1
C21: yuuu VS 雲天河（YYPKW） | J21: C VS F
C22: summer（三万匹磁力） VS 蜡笔大雪（雪批的奇妙冒险） | J22: D VS E
C23: summer（三万匹磁力） VS 雲天河（YYPKW） | J23: D VS F
C24: 蜡笔大雪（雪批的奇妙冒险） VS 雲天河（YYPKW） | J24: E VS F
A67: 🌧️ 微雨杯 S2「醉耀春锋」已开启报名 衷心感谢尤总、leo、马来王子、廷总、晓锅匠（排名不分先后）慷慨相助，以热忱护热爱，以心意赴赛场，让每一份拼搏都有荣光可赴。 微雨杯 S2「醉耀春锋」赛制将在S1赛制基础上进行优化升级。确保每个参赛选手获得更公平、更均衡、更有趣的游戏体验。 🏆 战队名次之赏 🥇 冠军战队 •葡萄白酒🍇🍶×1：以清冽琼浆，敬登顶之荣耀 •智力斗篷挂饰🧙‍♂️×1：以魔法之纹，承运筹之智慧 •自选 DOTA2 冰箱贴🧊×1：以方寸印记，藏赛场之回忆 •队长专属：敦煌福鹿呈祥杯🥂×1：以祥瑞之器，载战队之锋芒 🥈 亚军战队 •智力斗篷挂饰🧙‍♂️×1 •自选 DOTA2 冰箱贴🧊×1 •队长专属：敦煌福鹿呈祥杯🥂×1 🥉 季军战队 •自选 DOTA2 冰箱贴🧊×1 •队长专属：敦煌福鹿呈祥杯🥂×1 🎙️ 解说专属馈赠 所有解说均可获得解说积分，可兑换各类 DOTA2 周边 🎁 解说小肥羊、苹果君，另赠马来西亚特产巧克力 🍫，以一缕甜意，致谢声声相伴。 🌟 个人数据殊荣 以数据证锋芒，以坚守换嘉奖。 本赛季各位置佼佼者，将获天府鱼子酱 🥢： •分均经济最高・一号位 •分均经验最高・二号位 •承伤/经济最高・三号位 •参战最高・四号位 •助攻最多・五号位 ⚔️ 趣味 SOLO 赛 赛季同期开放SOLO 挑战赛，各路英雄可孤身赴战 胜者将获神秘惊喜奖品，悬念静待揭晓 ✨ 愿微雨为伴，举杯共竞； 以热爱为刃，以兄弟为盾，不负每一场奔赴。 ***特别注意：** 1.比赛中禁止嘲讽、压力、辱骂队友与对手，文明竞技，尊重每一位选手。 2.请确认自身时间可正常参赛，尽量避免多次迟到、无故弃赛。 若违反以上规定，上帝有权直接斩杀。 报名链接：https://wj.qq.com/s2/25994373/df52/ 报名前请确保已填写群表格并参与过内战（见群公告） 更多dota2周边👇 淘宝：微雨dota2

Sheet S2拍卖
A1: 🏆S1冠军🏆为：21、洋芋、黑色柳丁、柬埔寨智慧笼、coconut
A2: 序号 | B2: 微信昵称 | C2: 战力 | D2: 分数 | E2: 主选定位 | F2: 次选定位 | G2: 内冠次数 | H2: 自我介绍
A3: 1 | B3: 风Ain-t | C3: 88 | D3: 8750 | E3: 一 | F3: 二、三 | G3: 1 | H3: cc是我师傅（热辣舞男） | L3: 战力 | M3: 剩余金额 | P3: 战力 | Q3: 剩余金额
A4: 2 | B4: 笑败 | C4: 84 | D4: 8330 | E4: 一 | F4: 三 | G4: 4 | H4: 一三摇摆，二也能摇 | J4: 兆焱 | K4: 330 | L4: 90 | M4: =K4-K5-K6-K7-K8 -> 0 | N4: 秋 | O4: 330 | P4: 90 | Q4: =O4-O5-O6-O7-O8 -> 0
A5: 3 | B5: 蒙面加菲猫 | C5: 83 | D5: 8600 | E5: 一 | G5: 1 | J5: Drugz | K5: 150 | L5: 83 | N5: 小牛 | O5: 160 | P5: 75
A6: 4 | B6: 猪 | C6: 83 | D6: 8000 | E6: 四 | F6: 三 | G6: 1 | H6: 长的算了也就算了，打的也这么算了。 | J6: Ninelie | K6: 120 | L6: 70 | N6: END | O6: 75 | P6: 58
A7: 5 | B7: Drugz | C7: 82 | D7: 8900 | E7: 三 | F7: 四 | G7: 0 | H7: 哭胜（男同） | J7: 招财喵 | K7: 30 | L7: 30 | N7: dalinya. | O7: 30 | P7: 45
A8: 6 | B8: 阿魂呐 | C8: 81 | D8: 7500 | E8: 二 | G8: 2 | H8: 只想干笑败 | J8: 幺鸡 | K8: 30 | L8: 44 | N8: 你也喜欢河马嘛 | O8: 65 | P8: 53
A9: 7 | B9: 踏雾 | C9: 80 | D9: 8000 | E9: 一 | G9: 0 | L9: =SUM(L4:L8) -> 317 | P9: =SUM(P4:P8) -> 321
A10: 8 | B10: Sdy | C10: 78 | D10: 7800 | E10: 二 | F10: 三 | G10: 0 | H10: 一年半以前8100，后面没打过大号天梯了 | L10: 战力 | M10: 剩余金额 | P10: 战力 | Q10: 剩余金额
A11: 9 | B11: iqbs | C11: 77 | D11: 7700 | E11: 四 | F11: 三、五 | G11: 2 | H11: 笑败粉丝 | J11: 赤夜紫雨 | K11: 330 | L11: 89 | M11: =K11-K12-K13-K14-K15 -> 0 | N11: 蜡笔大雪 | O11: 335 | P11: 88 | Q11: =O11-O12-O13-O14-O15 -> 0
A12: 10 | B12: 黑色柳丁🏆 | C12: 76 | D12: 6500 | E12: 一、二、三 | F12: 四、五 | G12: 0 | H12: 笑败大神铁粉丝（忧郁王子） | J12: 荼霏 | K12: 160 | L12: 75 | N12: 哞哞 | O12: 75 | P12: 65
A13: 11 | B13: 21🏆 | C13: 75 | D13: 6800 | E13: 一 | G13: 1 | H13: 脚踢风仔的一（可爱水豚） | J13: 黑山羊 | K13: 70 | L13: 50 | N13: 蜡笔小雪 | O13: 100 | P13: 60
A14: 12 | B14: 小牛 | C14: 75 | D14: 7500 | E14: 二 | G14: 3 | H14: Dota思想家 | J14: 熊 | K14: 60 | L14: 55 | N14: ） | O14: 80 | P14: 60
A15: 13 | B15: 荼霏 | C15: 75 | D15: 6800 | E15: 二 | F15: 一、三、五 | G15: 1 | J15: 授法 | K15: 40 | L15: 44 | N15: PP | O15: 80 | P15: 45
A16: 14 | B16: Ninelie | C16: 70 | D16: 6800 | E16: 一 | F16: 四 | G16: 0 | H16: 儒雅随和 | L16: =SUM(L11:L15) -> 313 | P16: =SUM(P11:P15) -> 318
A17: 15 | B17: 柬埔寨智慧笼🏆 | C17: 68 | D17: 6000 | E17: 一、二 | G17: 0 | H17: 超级大稿子 | L17: 战力 | M17: 剩余金额 | P17: 战力 | Q17: 剩余金额
A18: 16 | B18: 哞哞 | C18: 65 | D18: 4300 | E18: 二 | F18: 三 | G18: 1 | H18: 混子中 | J18: 大蟑螂 | K18: 335 | L18: 87 | M18: =K18-K19-K20-K21-K22 -> 0 | N18: 所念皆星河 | O18: 340 | P18: 85 | Q18: =O18-O19-O20-O21-O22 -> 0
A19: 17 | B19: 睡衣大大 | C19: 63 | D19: 6000 | E19: 二 | F19: 一 | G19: 2 | H19: 老毕登 | J19: 笑败 | K19: 180 | L19: 84 | N19: Sdy | O19: 180 | P19: 78
A20: 18 | B20: 洋芋🏆 | C20: 60 | D20: 5900 | E20: 五 | F20: 三、四 | G20: 0 | H20: 听话 | J20: 风 | K20: 65 | L20: 50 | N20: vamoose | O20: 65 | P20: 55
A21: 19 | B21: 蜡笔小雪 | C21: 60 | D21: 6000 | E21: 三 | G21: 3 | H21: 三是扛起进攻大旗的猛男，不是你们口中的贱狗（帅哥）（雨一三） | J21: 清欢不渡 | K21: 40 | L21: 45 | N21: ZMJ 玖黎 | O21: 45 | P21: 50
A22: 20 | B22: ） | C22: 60 | D22: 6000 | E22: 一 | F22: 二、三 | J22: 绮怀. | K22: 50 | L22: 28 | N22: No | O22: 50 | P22: 33
A23: 21 | B23: 温酒 | C23: 60 | D23: 6000 | E23: 四 | F23: 五 | G23: 0 | H23: 太久没玩，需要复建，现在有点菜 | L23: =SUM(L18:L22) -> 294 | P23: =SUM(P18:P22) -> 301
A24: 22 | B24: Jose | C24: 59 | D24: 6200 | E24: 三 | F24: 四、五 | G24: 2 | H24: 没办法兄弟，我穷点没事，三是这样的，尽力了我的吧 | L24: 战力 | M24: 剩余金额 | P24: 战力 | Q24: 剩余金额
A25: 23 | B25: END | C25: 58 | D25: 6000 | E25: 一 | F25: 五 | G25: 1 | H25: 我是笑败的忠臣 | J25: YuuU | K25: 360 | L25: 77 | M25: =K25-K26-K27-K28-K29 -> 0 | N25: 云天河 | O25: 360 | P25: 76 | Q25: =O25-O26-O27-O28-O29 -> 0
A26: 24 | B26: yu | C26: 56 | D26: 5600 | E26: 三 | F26: 四 | G26: 0 | H26: 保抢我无敌 | J26: 踏雾 | K26: 140 | L26: 80 | N26: 蒙面加菲猫 | O26: 175 | P26: 83
A27: 25 | B27: 龙城林子 | C27: 55 | D27: 4100 | E27: 二 | F27: 四 | J27: 睡衣大大 | K27: 110 | L27: 63 | N27: 温酒 | O27: 60 | P27: 60
A28: 26 | B28: 王亚祈 | C28: 55 | D28: 5500 | E28: 一、四、五 | J28: 芋头芭乐脑袋 | K28: 55 | L28: 34 | N28: yu | O28: 95 | P28: 56
A29: 27 | B29: vamoose | C29: 55 | D29: 5500 | E29: 四、五 | F29: 一、三 | J29: 爱喝可乐的帅哥 | K29: 55 | L29: 42 | N29: 老K | O29: 30 | P29: 40
A30: 28 | B30: 熊 | C30: 55 | D30: 5000 | E30: 四、五 | G30: 0 | H30: 臭酱油一枚 | L30: =SUM(L25:L29) -> 296 | P30: =SUM(P25:P29) -> 315
A31: 29 | B31: 临江仙 | C31: 54 | D31: 5000 | E31: 一 | F31: 四 | L31: 战力 | M31: 剩余金额 | P31: 战力 | Q31: 剩余金额
A32: 30 | B32: 你也喜欢河马嘛 | C32: 53 | D32: 5300 | E32: 三、四、五 | F32: 一、二 | G32: 0 | H32: 新人求不虐 | J32: summer丶夏 | K32: 375 | L32: 68 | M32: =K32-K33-K34-K35-K36 -> 5 | N32: coconut🏆 | O32: 380 | P32: 64 | Q32: =O32-O33-O34-O35-O36 -> 0
A33: 31 | B33: ZMJ 玖黎 | C33: 52 | D33: 5800 | E33: 一、二 | F33: 三 | G33: 1 | H33: 佛系青年 | J33: 21🏆 | K33: 105 | L33: 75 | N33: 洋芋🏆 | O33: 85 | P33: 60
A34: 32 | B34: 黑山羊 | C34: 50 | D34: 4900 | E34: 二、五 | F34: 三、四 | G34: 2 | H34: ✌️😛✌️ | J34: iqbs | K34: 170 | L34: 77 | N34: 柬埔寨智慧笼🏆 | O34: 125 | P34: 68
A35: 33 | B35: 。。~ | C35: 50 | D35: 5000 | E35: 一、二、三、四、五 | G35: 0 | H35: pp | J35: 龙城林子 | K35: 40 | L35: 55 | N35: Jose | O35: 95 | P35: 59
A36: 34 | B36: 风 | C36: 50 | D36: 5000 | E36: 三 | F36: 一 | G36: 0 | H36: 复建选手 | J36: 忧郁的苹果君 | K36: 55 | L36: 30 | N36: 。。~ | O36: 75 | P36: 50
A37: 35 | B37: PP | C37: 45 | D37: 4990 | E37: 五 | F37: ppp | G37: 2 | H37: 对你的爱就像屎拉裤兜里 沉甸甸的 只有我自己知道 | L37: =SUM(L32:L36) -> 305 | P37: =SUM(P32:P36) -> 301
A38: 36 | B38: dalinya. | C38: 45 | D38: 4500 | E38: 二 | F38: 四 | G38: 0 | H38: QWQ | L38: 战力 | M38: 剩余金额 | P38: 战力 | Q38: 剩余金额
A39: 37 | B39: 授法 | C39: 44 | D39: 4500 | E39: 三 | F39: 一 | G39: 0 | H39: 很会抗压，不只玩憋壳形3。 | J39: starling | K39: 430 | L39: 34 | M39: =K39-K40-K41-K42-K43 -> 0 | N39: 尤也 | O39: 435 | P39: 30 | Q39: =O39-O40-O41-O42-O43 -> 0
A40: 38 | B40: 幺鸡 | C40: 44 | D40: 3800 | E40: 三、四 | F40: 五 | G40: 2 | H40: 不准欺负狗屎心念！换我来！ | J40: 风Ain-t | K40: 195 | L40: 88 | N40: 阿魂呐 | O40: 160 | P40: 81
...

Sheet 微雨杯比赛规则
F1: 🏆 微雨杯·规则
F2: 🚨️勿踩红线 ▸ 小号、谎报分数是红线，第一要义打造无小号比赛 ▸ 一旦抓住装猪装龙行为，被骂是小事，各社区互通是大事 💬 参赛须知 ▸ 参加过内战方可报名比赛 ▸ 别怕自己分低不敢打，你分越低，你的队友越强 ▸ 严禁攻击/辱骂选手，违者严肃处理
F4: 🔄 替补规则 | H4: ⚠️ 迟到判罚 | I4: ⏸️ 暂停规则
F5: 👥 替补资格： | G5: 可从未报名但参加过内战的群友中选取 | H5: 🕒 10分钟 ~ 15分钟 罚没BP时间 30秒 | I5: 每局、每队累计最多10分钟
F6: 🔢 数量限制： | G6: 每队最多允许1名替补 | H6: 🕓 15分钟 ~ 30分钟 罚没BP时间 90秒
F7: ⚔ 战力要求： | G7: •替补战力需比原选手低至少-5战力 | H7: 🛑 超过30分钟 直接判负
G8: •若原选手战力低于30，则替补不受此限
F9: 📝 报备流程： | G9: •必须提前向主办方报备，严禁临时替补
G10: •如遇突发情况，需及时与主办方沟通说明
F11: 🔄 出场次数： | G11: 替补选手出场次数不得超整个赛事半数
F12: 🚫 退赛处理细则
F13: ⛔ 选手处罚：无故退赛者，直接禁赛处理
F14: 👥 邀请人连带责任：该选手的邀请人三个月内禁止邀请新人参赛或入群
F15: 🔄 组委会补位机制：队员退赛后，由组委会负责安排原选手战力-3并参与过内战的一位相同位置、稳定替补补位

Sheet S2名单
A1: 序号 | B1: 微信昵称 | C1: steamid | D1: 战力 | E1: 分数 | F1: 擅长位置 | G1: 内战冠军次数 | H1: 自我介绍
A2: 1 | B2: 兆焱 | C2: 176191301 | D2: 90 | E2: 8900 | F2: 二 | G2: 2 | H2: 上帝
A3: 2 | B3: 秋 | C3: 1004877057 | D3: 90 | E3: 9000 | F3: 一,二,三,四 | G3: 2 | H3: 脚踢小雪，拳打鱼畜
A4: 3 | B4: 赤夜紫雨 | C4: 187933845 | D4: 89 | E4: 8100 | F4: 一,三 | G4: 1 | H4: 武痴
A5: 4 | B5: 蜡笔大雪 | C5: 187468758 | D5: 88 | E5: 9000 | F5: 三,四,五,一 | G5: 1 | H5: 精品洋葱头（专治扛起进攻大旗的三号位，超级贱狗）
A6: 5 | B6: 风Ain-t | C6: 136801289 | D6: 88 | E6: 8750 | F6: 一 | G6: 1 | H6: cc是我师傅（热辣舞男）
A7: 6 | B7: 大蟑螂 | C7: 341670770 | D7: 87 | E7: 9000 | F7: 二 | G7: 1 | H7: 保雨派
A8: 7 | B8: 所念皆星河 | C8: 381057664 | D8: 85 | E8: 8500 | F8: 一,二 | G8: 1 | H8: 温文尔雅
A9: 8 | B9: 笑败 | C9: 106964785 | D9: 84 | E9: 8330 | F9: 一 | G9: 4 | H9: 一三摇摆，二也能摇
A10: 9 | B10: 蒙面加菲猫 | C10: 299227181 | D10: 83 | E10: 8600 | F10: 一,三 | G10: 1
A11: 10 | B11: 猪 | C11: 266088396 | D11: 83 | E11: 8000 | F11: 三,四,五 | G11: 1 | H11: 长的算了也就算了，打的也这么算了。
A12: 11 | B12: Drugz | C12: 137306952 | D12: 82 | E12: 8900 | F12: 三 | G12: 0 | H12: 哭胜（男同）
A13: 12 | B13: 阿魂呐 | C13: 138558413 | D13: 81 | E13: 7500 | F13: 二 | G13: 2 | H13: 只想干笑败
A14: 13 | B14: 踏雾 | C14: 164613165 | D14: 80 | E14: 8000 | F14: 一 | G14: 0 | H14: 0
A15: 14 | B15: Sdy | C15: 173964673 | D15: 78 | E15: 7800 | F15: 二,三 | G15: 0 | H15: 一年半以前8100，后面没打过大号天梯了
A16: 15 | B16: iqbs | C16: 383560624 | D16: 77 | E16: 7700 | F16: 四,五,三 | G16: 2 | H16: 笑败粉丝
A17: 16 | B17: YuuU | C17: 885588023 | D17: 77 | E17: 7000 | F17: 一,二,三,四,五 | G17: 0 | H17: ？
A18: 17 | B18: 云天河 | C18: 267719332 | D18: 76 | E18: 7000 | F18: 二,四,五 | G18: 1 | H18: 三猫一滚puck 拉席克女王小小，ling神毒唯
A19: 18 | B19: 黑色柳丁 | C19: 457383175 | D19: 76 | E19: 6500 | F19: 二 | G19: 0 | H19: 笑败大神铁粉丝（忧郁王子）
A20: 19 | B20: 21 | C20: 277443592 | D20: 75 | E20: 6800 | F20: 一 | G20: 1 | H20: 脚踢风仔的一号位（可爱水豚）
A21: 20 | B21: 一颗大白菜 | C21: 186753076 | D21: 75 | E21: 7500 | F21: 一,二,三 | G21: 0 | H21: 啥都会一点
A22: 21 | B22: 小牛 | C22: 1259908216 | D22: 75 | E22: 7500 | F22: 二 | G22: 3 | H22: Dota思想家
A23: 22 | B23: Ninelie | C23: 401464166 | D23: 70 | E23: 6800 | F23: 一,二,三,四,五 | G23: 0 | H23: 儒雅随和
A24: 23 | B24: Summer丶夏 | C24: 355328125 | D24: 68 | E24: 6649 | F24: 一,二,三,四,五 | G24: 2 | H24: 每个位置都可以打，眼位研究不多，需要练英雄扩池子
A25: 24 | B25: 柬埔寨智慧笼 | C25: 122810642 | D25: 68 | E25: 6000 | F25: 一,二,三,四,五 | G25: 0 | H25: 超级大稿子
A26: 25 | B26: 哞哞 | C26: 235611786 | D26: 65 | E26: 4300 | F26: 二 | G26: 1 | H26: 混子中
A27: 26 | B27: coconut | C27: 108868178 | D27: 64 | E27: 6000 | F27: 二 | G27: 0 | H27: 性价比中单。打谁都不怂 还什么都会
A28: 27 | B28: 睡衣大大 | C28: 104465635 | D28: 63 | E28: 6000 | F28: 一,二 | G28: 2 | H28: 老毕登
A29: 28 | B29: ） | C29: 334481697 | D29: 60 | E29: 6000 | F29: 一,二,三
A30: 29 | B30: 洋芋 | C30: 255882400 | D30: 60 | E30: 5900 | F30: 五,三,四 | G30: 0 | H30: 听话
A31: 30 | B31: 温酒 | C31: 117970934 | D31: 60 | E31: 6000 | F31: 四 | G31: 0 | H31: 太久没玩，需要复建，现在有点菜
A32: 31 | B32: 蜡笔小雪 | C32: 154029585 | D32: 60 | E32: 6000 | F32: 三 | G32: 3 | H32: 三号位是扛起进攻大旗的猛男，不是你们口中的贱狗（帅哥）（雨一三）
A33: 32 | B33: Jose | C33: 1255409177 | D33: 59 | E33: 6200 | F33: 三 | G33: 2 | H33: 没办法兄弟，我穷点没事，三号位是这样的，尽力了我的吧
A34: 33 | B34: END | C34: 354618808 | D34: 58 | E34: 6000 | F34: 一,五 | G34: 1 | H34: 我是笑败的忠臣
A35: 34 | B35: yu | C35: 283200408 | D35: 56 | E35: 5600 | F35: 三,四 | G35: 0 | H35: 保抢我无敌
A36: 35 | B36: 熊 | C36: 223646770 | D36: 55 | E36: 5000 | F36: 四,五 | G36: 0 | H36: 臭酱油一枚
A37: 36 | B37: 龙城林子 | C37: 117252110 | D37: 55 | E37: 4100 | F37: 二
A38: 37 | B38: 王亚祈 | C38: 417868870 | D38: 55 | E38: 5500 | F38: 一,四,五
A39: 38 | B39: vamoose | C39: 242739321 | D39: 55 | E39: 5500 | F39: 一,三,四,五
A40: 39 | B40: 临江仙 | C40: 140389337 | D40: 54 | E40: 5000 | F40: 一,二,四
...

Sheet S2
A1: 🌧️ 微雨杯 S2「醉耀春锋」已开启报名 衷心感谢尤总、leo、马来王子、廷总、晓锅匠（排名不分先后）慷慨相助，以热忱护热爱，以心意赴赛场，让每一份拼搏都有荣光可赴。 微雨杯 S2「醉耀春锋」赛制将在S1赛制基础上进行优化升级。确保每个参赛选手获得更公平、更均衡、更有趣的游戏体验。 🏆 战队名次之赏 🥇 冠军战队 •葡萄白酒🍇🍶×1：以清冽琼浆，敬登顶之荣耀 •智力斗篷挂饰🧙‍♂️×1：以魔法之纹，承运筹之智慧 •自选 DOTA2 冰箱贴🧊×1：以方寸印记，藏赛场之回忆 •队长专属：敦煌福鹿呈祥杯🥂×1：以祥瑞之器，载战队之锋芒 🥈 亚军战队 •智力斗篷挂饰🧙‍♂️×1 •自选 DOTA2 冰箱贴🧊×1 •队长专属：敦煌福鹿呈祥杯🥂×1 🥉 季军战队 •自选 DOTA2 冰箱贴🧊×1 •队长专属：敦煌福鹿呈祥杯🥂×1 🎙️ 解说专属馈赠 所有解说均可获得解说积分，可兑换各类 DOTA2 周边 🎁 解说小肥羊、苹果君，另赠马来西亚特产巧克力 🍫，以一缕甜意，致谢声声相伴。 🌟 个人数据殊荣 以数据证锋芒，以坚守换嘉奖。 本赛季各位置佼佼者，将获天府鱼子酱 🥢： •分均经济最高・一号位 •分均经验最高・二号位 •承伤/经济最高・三号位 •参战最高・四号位 •助攻最多・五号位 ⚔️ 趣味 SOLO 赛 赛季同期开放SOLO 挑战赛，各路英雄可孤身赴战 胜者将获神秘惊喜奖品，悬念静待揭晓 ✨ 愿微雨为伴，举杯共竞； 以热爱为刃，以兄弟为盾，不负每一场奔赴。 ***特别注意：** 1.比赛中禁止嘲讽、压力、辱骂队友与对手，文明竞技，尊重每一位选手。 2.请确认自身时间可正常参赛，尽量避免多次迟到、无故弃赛。 若违反以上规定，上帝有权直接斩杀。 报名链接：https://wj.qq.com/s2/25994373/df52/ 报名前请确保已填写群表格并参与过内战（见群公告） 更多dota2周边👇 淘宝：微雨dota2

Sheet 选手名单
B1: 微信昵称（群） | C1: 数字id | D1: 游戏昵称 | E1: 分数 | F1: 战力值（别填） | G1: 擅长位置 | H1: 内战冠军次数 | I1: 自我介绍
B2: 兆焱 | C2: 176191301 | D2: Mu | E2: 8900 | F2: 90 | G2: 二 | H2: ★★☆☆☆ | I2: 上帝
A3: 12 | B3: 秋 | C3: 1004877057 | D3: 秋 | E3: 9000 | F3: 90 | G3: 一,二,三,四 | H3: ★★☆☆☆ | I3: 脚踢小雪，拳打鱼畜
B4: zealot4u | C4: 177909188 | D4: zealot4u | E4: 9000 | F4: 90 | G4: 三 | H4: ★☆☆☆☆ | I4: 新手三号位害怕对线
A5: 13 | B5: 赤夜紫雨 | C5: 187933845 | D5: 赤夜紫雨 | E5: 8100 | F5: 89 | G5: 一,三 | H5: ★☆☆☆☆ | I5: 武痴
B6: 风Ain-t | C6: 136801289 | D6: - | E6: 8750 | F6: 88 | G6: 一 | H6: ★☆☆☆☆ | I6: cc是我师傅（热辣舞男）
B7: 蜡笔大雪 | C7: 187468758 | D7: 畜高八斗 | E7: 9000 | F7: 88 | G7: 三,四,五,一 | H7: ★☆☆☆☆ | I7: 精品洋葱头（专治扛起进攻大旗的三号位，超级贱狗）
A8: 23 | B8: 辞 | C8: 417861014 | D8: bon vayege | E8: 8300 | F8: 88 | G8: 一,二 | H8: ☆☆☆☆☆
A9: 7 | B9: 大蟑螂 | C9: 341670770 | D9: 火辣大蟑螂 | E9: 9000 | F9: 87 | G9: 二 | H9: ★☆☆☆☆ | I9: 保雨派
B10: AA酒水范子 | C10: 139963294 | D10: 冒险的寂灭 | E10: 8700 | F10: 87 | G10: 一 | H10: ☆☆☆☆☆
B11: G | C11: 213975274 | D11: iCccy | E11: 8700 | F11: 86 | G11: 一,二,三,四,五 | H11: ☆☆☆☆☆
B12: 所念皆星河 | C12: 381057664 | D12: 所念皆星河 | E12: 8500 | F12: 85 | G12: 一,二 | H12: ★☆☆☆☆ | I12: 温文尔雅
B13: defencex | C13: 138235055 | D13: D | E13: 8500 | F13: 85 | G13: 五 | H13: ☆☆☆☆☆
A14: 1 | B14: 笑败 | C14: 106964785 | D14: 笑败 | E14: 8330 | F14: 84 | G14: 一 | H14: ★★★★☆ | I14: 上帝小弟
A15: 34 | B15: 精品贵公子 | D15: oiii | E15: 8600 | F15: 83 | G15: 一,三 | H15: ★☆☆☆☆
B16: 狮子麒麟凤 | C16: 266088396 | D16: 矮猪 | E16: 8000 | F16: 83 | G16: 三,四,五 | H16: ★☆☆☆☆ | I16: 长的算了也就算了，打的也这么算了。
B17: 晗 | D17: 小晗 | E17: 8300 | F17: 83 | G17: 一,二,三,四 | H17: ☆☆☆☆☆
B18: drugz | C18: 137306952 | D18: Tourbillion | E18: 8900 | F18: 82 | G18: 三 | H18: ☆☆☆☆☆ | I18: 哭胜（男同）
A19: 10 | B19: 阿魂呐 | C19: 138558413 | D19: 阿魂 | E19: 7500 | F19: 81 | G19: 二 | H19: ★★☆☆☆ | I19: 只想干笑败
B20: MBP | C20: 131584904 | D20: Mbppe | E20: 7500 | F20: 80 | G20: 一 | H20: ☆☆☆☆☆
B21: y | C21: 207704824 | D21: 做个好梦吧 | E21: 8300 | F21: 80 | G21: 一,二,四,五 | H21: ☆☆☆☆☆ | I21: A
B22: 12345 | C22: 348785399 | D22: ditto | E22: 8000 | F22: 80 | G22: 一,三,四,五 | H22: ☆☆☆☆☆
B23: 踏雾 | C23: 164613165 | D23: 空识茄蓝 | E23: 8000 | F23: 80 | G23: 一 | H23: ☆☆☆☆☆
B24: 大熊小清新 | C24: 136314899 | D24: Ursamajor | E24: 7800 | F24: 78 | G24: 二 | H24: ☆☆☆☆☆ | I24: 英雄针
B25: sdy | C25: 173964673 | D25: SomeD1eYoung | E25: 7800 | F25: 78 | G25: 二,三 | H25: ☆☆☆☆☆ | I25: 一年半以前8100，后面没打过大号天梯了
A26: 25 | B26: iqbs | C26: 383560624 | D26: 琴葉葵 | E26: 7700 | F26: 77 | G26: 四,五,三 | H26: ★★☆☆☆ | I26: 笑败粉丝
B27: Mago | C27: 136495866 | D27: ll mago | E27: 7700 | F27: 77 | G27: 二 | H27: ☆☆☆☆☆
A28: 27 | B28: YuuU | C28: 885588023 | D28: 赫尔 | E28: 7000 | F28: 77 | G28: 一,二,三,四,五 | H28: ☆☆☆☆☆ | I28: ？
A29: 24 | B29: 雲天河 | C29: 267719332 | D29: 雲天河 | E29: 6500 | F29: 76 | G29: 二,四,五 | H29: ★☆☆☆☆ | I29: 三猫一滚puck 拉席克女王小小，ling神毒唯
A30: 32 | B30: 黑色柳丁 | C30: 457383175 | D30: 黑色柳丁 | F30: 76 | G30: 二 | H30: ☆☆☆☆☆ | I30: 笑败大神铁粉丝（忧郁王子）
A31: 26 | B31: 小牛 | C31: 1259908216 | D31: Wjr. | E31: 7500 | F31: 75 | G31: 二 | H31: ★★★☆☆ | I31: Dota思想家
A32: 30 | B32: 荼霏 | C32: 137852652 | D32: Mortis | E32: 6800 | F32: 75 | G32: 一,二,四,五 | H32: ★☆☆☆☆
A33: 19 | B33: 21 | C33: 277443592 | D33: 21 | E33: 6800 | F33: 75 | G33: 一 | H33: ★☆☆☆☆ | I33: 脚踢风仔的一号位（可爱水豚）
B34: 日月同错 | C34: 168741476 | D34: 颾浪剑客 | E34: 7700 | F34: 75 | G34: 一,三,四,五 | H34: ☆☆☆☆☆ | I34: 颾浪剑客（笑败的刺客）
B35: shrike | C35: 364668381 | D35: 何春秋 | E35: 7500 | F35: 75 | G35: 一,二,三,四,五 | H35: ☆☆☆☆☆ | I35: 饶命
A36: 2 | B36: 一颗大白菜 | C36: 186753076 | D36: 一颗大白菜 | E36: 7500 | F36: 75 | G36: 一,二,三 | H36: ☆☆☆☆☆ | I36: 啥都会一点
B37: tiNy | C37: 195565104 | D37: 芬里厄 | E37: 7400 | F37: 74 | G37: 一,二 | H37: ☆☆☆☆☆
A38: 28 | B38: BLY | C38: 323934704 | D38: 天命 | E38: 6400 | F38: 72 | G38: 一 | H38: ★☆☆☆☆ | I38: j'h'h'j'h'j
B39: 车长老 | C39: 299025900 | D39: 酸酸奶盐 | E39: 7500 | F39: 72 | G39: 二 | H39: ☆☆☆☆☆ | I39: 不爱说话，单线程，听指挥
B40: Desperado | C40: 284456126 | D40: Desperado | E40: 7500 | F40: 72 | G40: 一 | H40: ☆☆☆☆☆
...

Sheet 微雨杯赛季记录
A1: 赛季 | B1: 名称 | C1: 冠军
A2: S1 | B2: 马国臻巧 | C2: 柬埔寨fy
C3: 黑色柳丁
C4: 21
C5: coconut
C6: 洋芋
A7: S2 | B7: 醉耀春锋

Sheet S2名单(草稿)
A1: 结束答题时间 | B1: 微信昵称 | D1: steamid | E1: 是否愿意成为队长
A2: 46097.633 | B2: 笑败 | C2: 笑败 | D2: 106964785 | E2: 否 | F2: 杜麦尼、老K、小刘、kevin未打过内战
A3: 46097.637 | B3: 授法 | C3: 授法 | D3: 370449300 | E3: 否
A4: 46097.637 | B4: 21 | C4: 21 | D4: 277443592 | E4: 否
A5: 46097.637 | B5: ） | C5: ） | D5: 334481697 | E5: 否
A6: 46097.637 | B6: 兆焱 | C6: 兆焱 | D6: 176191301 | E6: 是
A7: 46097.638 | B7: 大蟑螂 | C7: 大蟑螂 | D7: 341670770 | E7: 是
A8: 46097.638 | B8: PP | C8: PP | D8: 320479234 | E8: 否
A9: 46097.638 | B9: Summer丶夏 | C9: Summer丶夏 | D9: 355328125 | E9: 是
A10: 46097.639 | B10: ZMJ 玖黎 | C10: ZMJ 玖黎 | D10: 208333479 | E10: 否
A11: 46097.639 | B11: iqbs | C11: iqbs | D11: 383560624 | E11: 否
A12: 46097.639 | B12: 熊 | C12: 熊 | D12: 223646770 | E12: 否
A13: 46097.639 | B13: 洋芋 | C13: 洋芋 | D13: 255882400 | E13: 否
A14: 46097.64 | B14: 一颗大白菜 | C14: 一颗大白菜 | D14: 186753076 | E14: 是
A15: 46097.642 | B15: 芋头芭乐脑袋 | C15: 芋头芭乐脑袋 | D15: 168661508 | E15: 否
A16: 46097.642 | B16: 睡衣大大 | C16: 睡衣大大 | D16: 104465635 | E16: 否
... A21: 46097.647 | B21: 云天河 | C21: 云天河 | D21: 267719332 | E21: 是
A22: 46097.649 | B22: 芳心纵火犯 | C22: 芳心纵火犯 | D22: Leo. | E22: 否
A23: 46097.65 | B23: 蜡笔大雪 | C23: 蜡笔大雪 | D23: 畜高八斗 | E23: 否
A24: 46097.652 | B24: 赤夜紫雨 | C24: 赤夜紫雨 | D24: 187933845 | E24: 否
A25: 46097.653 | B25: Drugz | C25: Drugz | D25: 137306952 | E25: 否
A26: 46097.653 | B26: dalinya. | C26: dalinya. | D26: 李秀莲 | E26: 否
A27: 46097.655 | B27: 大蟑螂 | C27: 大蟑螂 | D27: 341670770 | E27: 是
A28: 46097.655 | B28: 临江仙 | C28: 临江仙 | D28: 140389337 | E28: 否
A29: 46097.663 | B29: 柬埔寨智慧笼 | C29: 柬埔寨智慧笼 | D29: 122810642 | E29: 否
A30: 46097.663 | B30: 老K | C30: 老K | D30: 148343069 | E30: 否
A31: 46097.669 | B31: 你也喜欢河马嘛 | C31: 你也喜欢河马嘛 | D31: 189497913 | E31: 否
A32: 46097.672 | B32: 哞哞 | C32: 哞哞 | D32: 235611786 | E32: 否
A33: 46097.672 | B33: 风 | C33: 风 | D33: 178988576 | E33: 否
A34: 46097.674 | B34: coconut | C34: coconut | D34: 108868178 | E34: 是
A35: 46097.675 | B35: 蒙面加菲猫 | C35: 蒙面加菲猫 | D35: 精品陪 | E35: 否
A36: 46097.675 | B36: 秋 | C36: 秋 | D36: 1004877057 | E36: 否
A37: 46097.676 | B37: 杜麦尼 | C37: #N/A | D37: 157424993 | E37: 否
A38: 46097.681 | B38: 温酒 | C38: 温酒 | D38: 117970934 | E38: 否
A39: 46097.689 | B39: YuuU | C39: YuuU | D39: 885588023 | E39: 是
A40: 46097.69 | B40: starling | C40: starling | D40: 400294058 | E40: 是
A41: 46097.692 | B41: 黑色柳丁 | C41: 黑色柳丁 | D41: 457383175 | E41: 否
A42: 46097.693 | B42: 踏雾 | C42: 踏雾 | D42: 164613165 | E42: 否
A43: 46097.699 | B43: No | C43: No | D43: 124599786 | E43: 否
A44: 46097.733 | B44: 招财喵 | C44: 招财喵 | D44: 136636318 | E44: 否
...

Sheet 截至20260318参加过内战名单
A1: 兆焱
A2: Summer丶夏
A3: 懂王
A4: nox
A5: 绮怀.
A6: Tourbillion
A7: 21
A8: 天命
A9: luyaju
A10: 鸭嘴兽
A11: 老佛
A12: 笑败
A13: 风六六
A14: 风九九
A15: 花基
A16: 风
A17: 雲天河
A18: DouYin38036......
A19: kaze
... A62: 普通朋友
A63: 21
A64: 天命
A65: 熟张
A66: 踏雾
A67: Summer丶夏
A68: 春雨
A69: 临江仙
A70: nox
A71: Summer丶夏
A72: 懂王
A73: 雲天河
A74: 你也喜欢河马嘛
A75: 花基
... A111: Z
A112: 21
A113: 柬埔寨fy
A114: 恕
A115: 绮怀.
A116: 兆焱
A117: PP
...

Sheet 拍卖规则
A2: 拍卖时间：2026年3月19日 20:00 拍卖规则： 1.队长根据自身战力值不同，拍卖资金不同； 2.底价为战力值向下取整（如89战力值，拍卖价为80起），最低不能低于20； 3.队长有责任留足够底价，防止自己无法凑齐5人； 4.拍卖顺序采取阶梯式随机（如6000-8000打乱）。
A15: 平均战力*5*1.6-自己战力*1.6（90以上1.7

Sheet 为爱发电记录表
A1: 感谢所有热心群友为爱发电，排名不分先后
A2: 昵称 | B2: 赞助 | C2: 规则 | D2: 使用情况
A3: 微雨 | B3: 红包封面×16 | C3: 冠军
A4: 胡老师 | B4: 花唧唧鼠标垫 | C4: 暴走 | D4: 2.6上帝暴走
B5: 汉源车厘子啤酒6罐 | C5: 2.8KDA最高 | D5: 上帝
B6: 雅安藏茶（浓香型） | C6: 2.9KDA最高 | D6: 笑败
B7: 蔬果干 | C7: 2.10辅助助攻最多 | D7: 幺鸡
B8: 蔬果干 | C8: 2.11辅助死亡最少
B9: 100
B10: 苹果黄芪元气茶 | C10: 3.6
A11: 心念 | B11: 50 | C11: 2.7冠军 | D11: 已使用
B12: 100 | C12: 2.9冠军 | D12: 已使用
A13: 上帝 | B13: 100 | C13: 2.8冠军 | D13: 已使用
A14: jose | B14: 100 | C14: 2.11冠军
A15: 笑败 | B15: 100 | C15: 2.10冠军 | D15: 已使用
A16: leo | B16: 100 | C16: 2.12冠军
A17: 阿鱼 | B17: 200 | C17: 2.12 12348
A18: 廷总 | B18: 260 | C18: 解说每个bo3拿20
B19: 500 | C19: 解说积分换购
A20: 马来王子 | B20: 马来西亚特产巧克力×5 | C20: S1冠军
B21: 牧马人K100机械键盘鼠标 | C21: S1KDA最高
B22: 500 | C22: S2
A23: iqbs | B23: 100 | C23: 3.2-3.3内战
A24: ling | B24: 100 | C24: 3.4内战
A25: Z | B25: 100 | C25: 3.11内战
A26: BLY | B26: 100
A27: 爱喝可乐的帅哥 | B27: 100 | C27: S2
A28: 云天河 | B28: 100 | C28: 3.6助攻最高的妹妹 | E28: 致谢云天河老板倾情助力微雨杯 菱纱灵动，携侠风暖赛场； 梦璃清雅，蕴雅韵润初心。 双姝相映温柔在， 微雨相逢共此程。
B29: 100 | C29: 3.6妹妹均分
A30: 忧郁的苹果君 | B30: 100

Sheet 组委会名单
A1: 🌨 | B1: - | C1: 精品赞助商微雨老师
A2: 兆焱 | B2: 283980530 | C2: 精品上帝
A3: 笑败 | B3: 106964785 | C3: 精品副群主
A4: 小小Zuilekha | B4: 283980530 | C4: 精品秘书
A5: 🍒招财喵՞ | B5: 136636318 | C5: 精品脑子
A6: 齐梓轩Leo | B6: 137784091 | C6: 精品全能
A7: 这个夏天-北冥雪 | B7: 283980530 | C7: 精品小狗
A8: 反反反弹-廷总 | B8: 137306952 | C8: 精品PM
A9: 日月同错-骚骚 | B9: 283980530 | C9: 精品程序员
A10: bobobo | B10: 283980530 | C10: 精品打酱油
A11: 绮怀.-ling神 | B11: 283980530 | C11: 精品牛马
A12: 小肥羊 | C12: 精品解说A
A13: 忧郁的苹果君 | C13: 精品解说B

Sheet 0317内战
B1: 接龙序号 | C1: 微信昵称（群） | D1: 战力值 | E1: 数字id | F1: 参考分数 | G1: 擅长位置 | H1: 备注 | N1: 赛程（一晚上解决，突出一个短平快）
B2: 12 | C2: =VLOOKUP(B2,选手名单!A:I,2,0) -> 秋 | D2: =VLOOKUP(B2,选手名单!A:I,6,0) -> 90 | E2: =VLOOKUP(B2,选手名单!A:I,3,0) -> 1004877057 | F2: =VLOOKUP(B2,选手名单!A:I,5,0) -> 9000 | G2: =VLOOKUP(B2,选手名单!A:I,7,0) -> 一,二,三,四 | I2: 秋 | K2: 赤夜紫雨 | N2: A辞
B3: 13 | C3: =VLOOKUP(B3,选手名单!A:I,2,0) -> 赤夜紫雨 | D3: =VLOOKUP(B3,选手名单!A:I,6,0) -> 89 | E3: =VLOOKUP(B3,选手名单!A:I,3,0) -> 187933845 | F3: =VLOOKUP(B3,选手名单!A:I,5,0) -> 8100 | G3: =VLOOKUP(B3,选手名单!A:I,7,0) -> 一,三 | I3: 秋 | J3: 90 | K3: 赤夜紫雨 | L3: 89
B4: 23 | C4: =VLOOKUP(B4,选手名单!A:I,2,0) -> 辞 | D4: =VLOOKUP(B4,选手名单!A:I,6,0) -> 88 | E4: =VLOOKUP(B4,选手名单!A:I,3,0) -> 417861014 | F4: =VLOOKUP(B4,选手名单!A:I,5,0) -> 8300 | G4: =VLOOKUP(B4,选手名单!A:I,7,0) -> 一,二 | I4: 蜡笔小雪 | J4: 60 | K4: iqbs | L4: 77 | Q4: B秋
B5: 7 | C5: =VLOOKUP(B5,选手名单!A:I,2,0) -> 大蟑螂 | D5: =VLOOKUP(B5,选手名单!A:I,6,0) -> 87 | E5: =VLOOKUP(B5,选手名单!A:I,3,0) -> 341670770 | F5: =VLOOKUP(B5,选手名单!A:I,5,0) -> 9000 | G5: =VLOOKUP(B5,选手名单!A:I,7,0) -> 二 | I5: 小牛 | J5: 75 | K5: 睡衣大大 | L5: 63
B6: 1 | C6: =VLOOKUP(B6,选手名单!A:I,2,0) -> 笑败 | D6: =VLOOKUP(B6,选手名单!A:I,6,0) -> 84 | E6: =VLOOKUP(B6,选手名单!A:I,3,0) -> 106964785 | F6: =VLOOKUP(B6,选手名单!A:I,5,0) -> 8330 | G6: =VLOOKUP(B6,选手名单!A:I,7,0) -> 一 | I6: End | J6: 58 | K6: 王亚祈 | L6: 55 | N6: B秋
B7: 10 | C7: =VLOOKUP(B7,选手名单!A:I,2,0) -> 阿魂呐 | D7: =VLOOKUP(B7,选手名单!A:I,6,0) -> 81 | E7: =VLOOKUP(B7,选手名单!A:I,3,0) -> 138558413 | F7: =VLOOKUP(B7,选手名单!A:I,5,0) -> 7500 | G7: =VLOOKUP(B7,选手名单!A:I,7,0) -> 二 | I7: 军 | J7: 45 | K7: 寥寥 | L7: 40
B8: 25 | C8: =VLOOKUP(B8,选手名单!A:I,2,0) -> iqbs | D8: =VLOOKUP(B8,选手名单!A:I,6,0) -> 77 | E8: =VLOOKUP(B8,选手名单!A:I,3,0) -> 383560624 | F8: =VLOOKUP(B8,选手名单!A:I,5,0) -> 7700 | G8: =VLOOKUP(B8,选手名单!A:I,7,0) -> 四,五,三 | I8: 总分 | J8: =SUM(J3:J7) -> 328 | K8: 总分 | L8: =SUM(L3:L7) -> 324
B9: 27 | C9: =VLOOKUP(B9,选手名单!A:I,2,0) -> YuuU | D9: =VLOOKUP(B9,选手名单!A:I,6,0) -> 77 | E9: =VLOOKUP(B9,选手名单!A:I,3,0) -> 885588023 | F9: =VLOOKUP(B9,选手名单!A:I,5,0) -> 7000 | G9: =VLOOKUP(B9,选手名单!A:I,7,0) -> 一,二,三,四,五 | I9: 辞 | K9: 大蟑螂 | N9: C笑败
B10: 24 | C10: =VLOOKUP(B10,选手名单!A:I,2,0) -> 雲天河 | D10: =VLOOKUP(B10,选手名单!A:I,6,0) -> 76 | E10: =VLOOKUP(B10,选手名单!A:I,3,0) -> 267719332 | F10: =VLOOKUP(B10,选手名单!A:I,5,0) -> 6500 | G10: =VLOOKUP(B10,选手名单!A:I,7,0) -> 二,四,五 | I10: 辞 | J10: 88 | K10: 大蟑螂 | L10: 87
B11: 2 | C11: =VLOOKUP(B11,选手名单!A:I,2,0) -> 一颗大白菜 | D11: =VLOOKUP(B11,选手名单!A:I,6,0) -> 75 | E11: =VLOOKUP(B11,选手名单!A:I,3,0) -> 186753076 | F11: =VLOOKUP(B11,选手名单!A:I,5,0) -> 7500 | G11: =VLOOKUP(B11,选手名单!A:I,7,0) -> 一,二,三 | I11: YuuU | J11: 77 | K11: starling | L11: 34 | Q11: D赤夜紫雨
B12: 19 | C12: =VLOOKUP(B12,选手名单!A:I,2,0) -> 21 | D12: =VLOOKUP(B12,选手名单!A:I,6,0) -> 75 | E12: =VLOOKUP(B12,选手名单!A:I,3,0) -> 277443592 | F12: =VLOOKUP(B12,选手名单!A:I,5,0) -> 6800 | G12: =VLOOKUP(B12,选手名单!A:I,7,0) -> 一 | I12: 雲天河 | J12: 76 | K12: 21 | L12: 75 | W12: 🏆
B13: 26 | C13: =VLOOKUP(B13,选手名单!A:I,2,0) -> 小牛 | D13: =VLOOKUP(B13,选手名单!A:I,6,0) -> 75 | E13: =VLOOKUP(B13,选手名单!A:I,3,0) -> 1259908216 | F13: =VLOOKUP(B13,选手名单!A:I,5,0) -> 7500 | G13: =VLOOKUP(B13,选手名单!A:I,7,0) -> 二 | I13: 游牧骑兵 | J13: 40 | K13: 哞哞 | L13: 65 | N13: D赤夜紫雨
B14: 30 | C14: =VLOOKUP(B14,选手名单!A:I,2,0) -> 荼霏 | D14: =VLOOKUP(B14,选手名单!A:I,6,0) -> 75 | E14: =VLOOKUP(B14,选手名单!A:I,3,0) -> 137852652 | F14: =VLOOKUP(B14,选手名单!A:I,5,0) -> 6800 | G14: =VLOOKUP(B14,选手名单!A:I,7,0) -> 一,二,四,五 | I14: 风 | J14: 50 | K14: 芋头芭乐脑袋 | L14: 34
B15: 28 | C15: =VLOOKUP(B15,选手名单!A:I,2,0) -> BLY | D15: =VLOOKUP(B15,选手名单!A:I,6,0) -> 72 | E15: =VLOOKUP(B15,选手名单!A:I,3,0) -> 323934704 | F15: =VLOOKUP(B15,选手名单!A:I,5,0) -> 6400 | G15: =VLOOKUP(B15,选手名单!A:I,7,0) -> 一 | I15: 总分 | J15: =SUM(J10:J14) -> 331 | K15: 总分 | L15: =SUM(L10:L14) -> 295
B16: 22 | C16: =VLOOKUP(B16,选手名单!A:I,2,0) -> 哞哞 | D16: =VLOOKUP(B16,选手名单!A:I,6,0) -> 65 | E16: =VLOOKUP(B16,选手名单!A:I,3,0) -> 235611786 | F16: =VLOOKUP(B16,选手名单!A:I,5,0) -> 4300 | G16: =VLOOKUP(B16,选手名单!A:I,7,0) -> 二 | I16: 笑败 | K16: 阿魂 | N16: E阿魂
B17: 3 | C17: =VLOOKUP(B17,选手名单!A:I,2,0) -> 睡衣大大 | D17: =VLOOKUP(B17,选手名单!A:I,6,0) -> 63 | E17: =VLOOKUP(B17,选手名单!A:I,3,0) -> 104465635 | F17: =VLOOKUP(B17,选手名单!A:I,5,0) -> 6000 | G17: =VLOOKUP(B17,选手名单!A:I,7,0) -> 一,二 | I17: 笑败 | J17: 84 | K17: 阿魂呐 | L17: 81
B18: 5 | C18: =VLOOKUP(B18,选手名单!A:I,2,0) -> 蜡笔小雪 | D18: =VLOOKUP(B18,选手名单!A:I,6,0) -> 60 | E18: =VLOOKUP(B18,选手名单!A:I,3,0) -> 154029585 | F18: =VLOOKUP(B18,选手名单!A:I,5,0) -> 6000 | G18: =VLOOKUP(B18,选手名单!A:I,7,0) -> 三 | I18: 荼霏 | J18: 75 | K18: 你也喜欢河马嘛 | L18: 53 | Q18: E阿魂
B19: 6 | C19: =VLOOKUP(B19,选手名单!A:I,2,0) -> jose | D19: =VLOOKUP(B19,选手名单!A:I,6,0) -> 59 | E19: =VLOOKUP(B19,选手名单!A:I,3,0) -> 1255409177 | F19: =VLOOKUP(B19,选手名单!A:I,5,0) -> 6200 | G19: =VLOOKUP(B19,选手名单!A:I,7,0) -> 三 | I19: iceice | J19: 45 | K19: 一颗大白菜 | L19: 75
B20: 15 | C20: =VLOOKUP(B20,选手名单!A:I,2,0) -> End | D20: =VLOOKUP(B20,选手名单!A:I,6,0) -> 58 | E20: =VLOOKUP(B20,选手名单!A:I,3,0) -> 354618808 | F20: =VLOOKUP(B20,选手名单!A:I,5,0) -> 6000 | G20: =VLOOKUP(B20,选手名单!A:I,7,0) -> 一,五 | I20: BLY | J20: 72 | K20: jose | L20: 59 | N20: F大蟑螂
B21: 18 | C21: =VLOOKUP(B21,选手名单!A:I,2,0) -> 王亚祈 | D21: =VLOOKUP(B21,选手名单!A:I,6,0) -> 55 | E21: =VLOOKUP(B21,选手名单!A:I,3,0) -> 417868870 | F21: =VLOOKUP(B21,选手名单!A:I,5,0) -> 5500 | G21: =VLOOKUP(B21,选手名单!A:I,7,0) -> 一,四,五 | I21: 小橙皮～ | J21: 41 | K21: 。。~ | L21: 50
B22: 16 | C22: =VLOOKUP(B22,选手名单!A:I,2,0) -> 你也喜欢河马嘛 | D22: =VLOOKUP(B22,选手名单!A:I,6,0) -> 53 | E22: =VLOOKUP(B22,选手名单!A:I,3,0) -> 189497913 | F22: =VLOOKUP(B22,选手名单!A:I,5,0) -> 5300 | G22: =VLOOKUP(B22,选手名单!A:I,7,0) -> 一,二,三,四,五 | I22: 总分 | J22: =SUM(J17:J21) -> 317 | K22: 总分 | L22: =SUM(L17:L21) -> 318
B23: 8 | C23: =VLOOKUP(B23,选手名单!A:I,2,0) -> 。。~ | D23: =VLOOKUP(B23,选手名单!A:I,6,0) -> 50 | E23: =VLOOKUP(B23,选手名单!A:I,3,0) -> 136537289 | F23: =VLOOKUP(B23,选手名单!A:I,5,0) -> 5000 | G23: =VLOOKUP(B23,选手名单!A:I,7,0) -> 一,二,三,四
B24: 29 | C24: =VLOOKUP(B24,选手名单!A:I,2,0) -> 风 | D24: =VLOOKUP(B24,选手名单!A:I,6,0) -> 50 | E24: =VLOOKUP(B24,选手名单!A:I,3,0) -> 178988576 | F24: =VLOOKUP(B24,选手名单!A:I,5,0) -> 5000 | G24: =VLOOKUP(B24,选手名单!A:I,7,0) -> 一,三
B25: 4 | C25: =VLOOKUP(B25,选手名单!A:I,2,0) -> 军 | D25: =VLOOKUP(B25,选手名单!A:I,6,0) -> 45 | E25: =VLOOKUP(B25,选手名单!A:I,3,0) -> 77006306 | F25: =VLOOKUP(B25,选手名单!A:I,5,0) -> 4600 | G25: =VLOOKUP(B25,选手名单!A:I,7,0) -> 三,四 | Q25: F大蟑螂
B26: 11 | C26: =VLOOKUP(B26,选手名单!A:I,2,0) -> iceice | D26: =VLOOKUP(B26,选手名单!A:I,6,0) -> 45 | E26: =VLOOKUP(B26,选手名单!A:I,3,0) -> 0 | F26: =VLOOKUP(B26,选手名单!A:I,5,0) -> 5500 | G26: =VLOOKUP(B26,选手名单!A:I,7,0) -> 四,五
B27: 14 | C27: =VLOOKUP(B27,选手名单!A:I,2,0) -> 小橙皮～ | D27: =VLOOKUP(B27,选手名单!A:I,6,0) -> 41 | E27: =VLOOKUP(B27,选手名单!A:I,3,0) -> 228914641 | F27: =VLOOKUP(B27,选手名单!A:I,5,0) -> 4600 | G27: =VLOOKUP(B27,选手名单!A:I,7,0) -> 四,五
B28: 17 | C28: =VLOOKUP(B28,选手名单!A:I,2,0) -> 寥寥 | D28: =VLOOKUP(B28,选手名单!A:I,6,0) -> 40 | E28: =VLOOKUP(B28,选手名单!A:I,3,0) -> 158643480 | F28: =VLOOKUP(B28,选手名单!A:I,5,0) -> 4000 | G28: =VLOOKUP(B28,选手名单!A:I,7,0) -> 一,二,三,四,五
B29: 21 | C29: =VLOOKUP(B29,选手名单!A:I,2,0) -> 游牧骑兵 | D29: =VLOOKUP(B29,选手名单!A:I,6,0) -> 40 | E29: =VLOOKUP(B29,选手名单!A:I,3,0) -> 351772086 | F29: =VLOOKUP(B29,选手名单!A:I,5,0) -> 3000 | G29: =VLOOKUP(B29,选手名单!A:I,7,0) -> 三,四,五
B30: 9 | C30: =VLOOKUP(B30,选手名单!A:I,2,0) -> starling | D30: =VLOOKUP(B30,选手名单!A:I,6,0) -> 34 | E30: =VLOOKUP(B30,选手名单!A:I,3,0) -> 400294058 | F30: =VLOOKUP(B30,选手名单!A:I,5,0) -> 4000 | G30: =VLOOKUP(B30,选手名单!A:I,7,0) -> 四,五
B31: 20 | C31: =VLOOKUP(B31,选手名单!A:I,2,0) -> 芋头芭乐脑袋 | D31: =VLOOKUP(B31,选手名单!A:I,6,0) -> 34 | E31: =VLOOKUP(B31,选手名单!A:I,3,0) -> 168661508 | F31: =VLOOKUP(B31,选手名单!A:I,5,0) -> 3400 | G31: =VLOOKUP(B31,选手名单!A:I,7,0) -> 四,五

Sheet 0315内战
B1: 接龙序号 | C1: 微信昵称（群） | D1: 战力值 | E1: 数字id | F1: 参考分数 | G1: 擅长位置 | H1: 备注 | N1: 赛程（一晚上解决，突出一个短平快）
B2: 2 | C2: =VLOOKUP(B2,选手名单!A:I,2,0) -> 一颗大白菜 | D2: =VLOOKUP(B2,选手名单!A:I,6,0) -> 75 | E2: =VLOOKUP(B2,选手名单!A:I,3,0) -> 186753076 | F2: =VLOOKUP(B2,选手名单!A:I,5,0) -> 7500 | G2: =VLOOKUP(B2,选手名单!A:I,7,0) -> 一,二,三 | I2: 丫丫 | K2: 陈 | N2: 丫丫
B3: 3 | C3: =VLOOKUP(B3,选手名单!A:I,2,0) -> 睡衣大大 | D3: =VLOOKUP(B3,选手名单!A:I,6,0) -> 63 | E3: =VLOOKUP(B3,选手名单!A:I,3,0) -> 104465635 | F3: =VLOOKUP(B3,选手名单!A:I,5,0) -> 6000 | G3: =VLOOKUP(B3,选手名单!A:I,7,0) -> 一,二 | I3: 丫丫5 | J3: 25 | K3: 陈34 | L3: 40
B4: 4 | C4: =VLOOKUP(B4,选手名单!A:I,2,0) -> 军 | D4: =VLOOKUP(B4,选手名单!A:I,6,0) -> 45 | E4: =VLOOKUP(B4,选手名单!A:I,3,0) -> 77006306 | F4: =VLOOKUP(B4,选手名单!A:I,5,0) -> 4600 | G4: =VLOOKUP(B4,选手名单!A:I,7,0) -> 三,四 | I4: Ryoko凉子 | J4: 43 | K4: 反反反弹 | L4: 40 | N4: rd BO3
B5: 5 | C5: =VLOOKUP(B5,选手名单!A:I,2,0) -> 蜡笔小雪 | D5: =VLOOKUP(B5,选手名单!A:I,6,0) -> 60 | E5: =VLOOKUP(B5,选手名单!A:I,3,0) -> 154029585 | F5: =VLOOKUP(B5,选手名单!A:I,5,0) -> 6000 | G5: =VLOOKUP(B5,选手名单!A:I,7,0) -> 三 | I5: 游牧骑兵 | J5: 40 | K5: 绮怀. | L5: 28
B6: 13 | C6: =VLOOKUP(B6,选手名单!A:I,2,0) -> 赤夜紫雨 | D6: =VLOOKUP(B6,选手名单!A:I,6,0) -> 89 | E6: =VLOOKUP(B6,选手名单!A:I,3,0) -> 187933845 | F6: =VLOOKUP(B6,选手名单!A:I,5,0) -> 8100 | G6: =VLOOKUP(B6,选手名单!A:I,7,0) -> 一,三 | I6: 小乐 | J6: 32 | K6: starling | L6: 34 | N6: 陈
B7: 8 | C7: =VLOOKUP(B7,选手名单!A:I,2,0) -> 。。~ | D7: =VLOOKUP(B7,选手名单!A:I,6,0) -> 50 | E7: =VLOOKUP(B7,选手名单!A:I,3,0) -> 136537289 | F7: =VLOOKUP(B7,选手名单!A:I,5,0) -> 5000 | G7: =VLOOKUP(B7,选手名单!A:I,7,0) -> 一,二,三,四 | I7: 云南红豆汤 | J7: 20 | K7: 芋头芭乐脑袋 | L7: 34
B8: 11 | C8: =VLOOKUP(B8,选手名单!A:I,2,0) -> iceice | D8: =VLOOKUP(B8,选手名单!A:I,6,0) -> 45 | E8: =VLOOKUP(B8,选手名单!A:I,3,0) -> 0 | F8: =VLOOKUP(B8,选手名单!A:I,5,0) -> 5500 | G8: =VLOOKUP(B8,选手名单!A:I,7,0) -> 四,五 | I8: 总分 | J8: =SUM(J3:J7) -> 160 | K8: 总分 | L8: =SUM(L3:L7) -> 176
B9: 7 | C9: =VLOOKUP(B9,选手名单!A:I,2,0) -> 大蟑螂 | D9: =VLOOKUP(B9,选手名单!A:I,6,0) -> 87 | E9: =VLOOKUP(B9,选手名单!A:I,3,0) -> 341670770 | F9: =VLOOKUP(B9,选手名单!A:I,5,0) -> 9000 | G9: =VLOOKUP(B9,选手名单!A:I,7,0) -> 二
B16: 15 | C16: =VLOOKUP(B16,选手名单!A:I,2,0) -> End | D16: =VLOOKUP(B16,选手名单!A:I,6,0) -> 58 | E16: =VLOOKUP(B16,选手名单!A:I,3,0) -> 354618808 | F16: =VLOOKUP(B16,选手名单!A:I,5,0) -> 6000 | G16: =VLOOKUP(B16,选手名单!A:I,7,0) -> 一,五
B17: 16 | C17: =VLOOKUP(B17,选手名单!A:I,2,0) -> 你也喜欢河马嘛 | D17: =VLOOKUP(B17,选手名单!A:I,6,0) -> 53 | E17: =VLOOKUP(B17,选手名单!A:I,3,0) -> 189497913 | F17: =VLOOKUP(B17,选手名单!A:I,5,0) -> 5300 | G17: =VLOOKUP(B17,选手名单!A:I,7,0) -> 一,二,三,四,五
B18: 17 | C18: =VLOOKUP(B18,选手名单!A:I,2,0) -> 寥寥 | D18: =VLOOKUP(B18,选手名单!A:I,6,0) -> 40 | E18: =VLOOKUP(B18,选手名单!A:I,3,0) -> 158643480 | F18: =VLOOKUP(B18,选手名单!A:I,5,0) -> 4000 | G18: =VLOOKUP(B18,选手名单!A:I,7,0) -> 一,二,三,四,五
B19: 18 | C19: =VLOOKUP(B19,选手名单!A:I,2,0) -> 王亚祈 | D19: =VLOOKUP(B19,选手名单!A:I,6,0) -> 55 | E19: =VLOOKUP(B19,选手名单!A:I,3,0) -> 417868870 | F19: =VLOOKUP(B19,选手名单!A:I,5,0) -> 5500 | G19: =VLOOKUP(B19,选手名单!A:I,7,0) -> 一,四,五
B20: 19 | C20: =VLOOKUP(B20,选手名单!A:I,2,0) -> 21 | D20: =VLOOKUP(B20,选手名单!A:I,6,0) -> 75 | E20: =VLOOKUP(B20,选手名单!A:I,3,0) -> 277443592 | F20: =VLOOKUP(B20,选手名单!A:I,5,0) -> 6800 | G20: =VLOOKUP(B20,选手名单!A:I,7,0) -> 一
B21: 20 | C21: =VLOOKUP(B21,选手名单!A:I,2,0) -> 芋头芭乐脑袋 | D21: =VLOOKUP(B21,选手名单!A:I,6,0) -> 34 | E21: =VLOOKUP(B21,选手名单!A:I,3,0) -> 168661508 | F21: =VLOOKUP(B21,选手名单!A:I,5,0) -> 3400 | G21: =VLOOKUP(B21,选手名单!A:I,7,0) -> 四,五
B22: 7 | C22: =VLOOKUP(B22,选手名单!A:I,2,0) -> 大蟑螂 | D22: =VLOOKUP(B22,选手名单!A:I,6,0) -> 87 | E22: =VLOOKUP(B22,选手名单!A:I,3,0) -> 341670770 | F22: =VLOOKUP(B22,选手名单!A:I,5,0) -> 9000 | G22: =VLOOKUP(B22,选手名单!A:I,7,0) -> 二
B23: 9 | C23: =VLOOKUP(B23,选手名单!A:I,2,0) -> starling | D23: =VLOOKUP(B23,选手名单!A:I,6,0) -> 34 | E23: =VLOOKUP(B23,选手名单!A:I,3,0) -> 400294058 | F23: =VLOOKUP(B23,选手名单!A:I,5,0) -> 4000 | G23: =VLOOKUP(B23,选手名单!A:I,7,0) -> 四,五
B24: 10 | C24: =VLOOKUP(B24,选手名单!A:I,2,0) -> 阿魂呐 | D24: =VLOOKUP(B24,选手名单!A:I,6,0) -> 81 | E24: =VLOOKUP(B24,选手名单!A:I,3,0) -> 138558413 | F24: =VLOOKUP(B24,选手名单!A:I,5,0) -> 7500 | G24: =VLOOKUP(B24,选手名单!A:I,7,0) -> 二
B25: 12 | C25: =VLOOKUP(B25,选手名单!A:I,2,0) -> 秋 | D25: =VLOOKUP(B25,选手名单!A:I,6,0) -> 90 | E25: =VLOOKUP(B25,选手名单!A:I,3,0) -> 1004877057 | F25: =VLOOKUP(B25,选手名单!A:I,5,0) -> 9000 | G25: =VLOOKUP(B25,选手名单!A:I,7,0) -> 一,二,三,四
B26: 13 | C26: =VLOOKUP(B26,选手名单!A:I,2,0) -> 赤夜紫雨 | D26: =VLOOKUP(B26,选手名单!A:I,6,0) -> 89 | E26: =VLOOKUP(B26,选手名单!A:I,3,0) -> 187933845 | F26: =VLOOKUP(B26,选手名单!A:I,5,0) -> 8100 | G26: =VLOOKUP(B26,选手名单!A:I,7,0) -> 一,三
B27: 1 | C27: =VLOOKUP(B27,选手名单!A:I,2,0) -> 笑败 | D27: =VLOOKUP(B27,选手名单!A:I,6,0) -> 84 | E27: =VLOOKUP(B27,选手名单!A:I,3,0) -> 106964785 | F27: =VLOOKUP(B27,选手名单!A:I,5,0) -> 8330 | G27: =VLOOKUP(B27,选手名单!A:I,7,0) -> 一

Sheet 0313内战
B1: 接龙序号 | C1: 微信昵称（群） | D1: 战力值 | E1: 数字id | F1: 参考分数 | G1: 擅长位置 | H1: 备注 | N1: 赛程（一晚上解决，突出一个短平快）
B2: 20 | C2: =VLOOKUP(B2,选手名单!A:I,2,0) -> 芋头芭乐脑袋 | D2: =VLOOKUP(B2,选手名单!A:I,6,0) -> 34 | E2: =VLOOKUP(B2,选手名单!A:I,3,0) -> 168661508 | F2: =VLOOKUP(B2,选手名单!A:I,5,0) -> 3400 | G2: =VLOOKUP(B2,选手名单!A:I,7,0) -> 四,五 | I2: 蟑螂 | K2: 笑败 | N2: 蟑螂
B3: 7 | C3: =VLOOKUP(B3,选手名单!A:I,2,0) -> 大蟑螂 | D3: =VLOOKUP(B3,选手名单!A:I,6,0) -> 87 | E3: =VLOOKUP(B3,选手名单!A:I,3,0) -> 341670770 | F3: =VLOOKUP(B3,选手名单!A:I,5,0) -> 9000 | G3: =VLOOKUP(B3,选手名单!A:I,7,0) -> 二 | I3: 蟑螂 | J3: 87 | K3: 笑败 | L3: 84
B4: 18 | C4: =VLOOKUP(B4,选手名单!A:I,2,0) -> 王亚祈 | D4: =VLOOKUP(B4,选手名单!A:I,6,0) -> 55 | E4: =VLOOKUP(B4,选手名单!A:I,3,0) -> 417868870 | F4: =VLOOKUP(B4,选手名单!A:I,5,0) -> 5500 | G4: =VLOOKUP(B4,选手名单!A:I,7,0) -> 一,四,五 | I4: 游牧骑兵 | J4: 40 | K4: 忧郁的苹果君 | L4: 30 | N4: 第1组BO1 | Q4: 蟑螂
B5: 17 | C5: =VLOOKUP(B5,选手名单!A:I,2,0) -> 寥寥 | D5: =VLOOKUP(B5,选手名单!A:I,6,0) -> 40 | E5: =VLOOKUP(B5,选手名单!A:I,3,0) -> 158643480 | F5: =VLOOKUP(B5,选手名单!A:I,5,0) -> 4000 | G5: =VLOOKUP(B5,选手名单!A:I,7,0) -> 一,二,三,四,五 | I5: 小牛 | J5: 75 | K5: 赤夜紫雨 | L5: 89
B6: 14 | C6: =VLOOKUP(B6,选手名单!A:I,2,0) -> 小橙皮～ | D6: =VLOOKUP(B6,选手名单!A:I,6,0) -> 41 | E6: =VLOOKUP(B6,选手名单!A:I,3,0) -> 228914641 | F6: =VLOOKUP(B6,选手名单!A:I,5,0) -> 4600 | G6: =VLOOKUP(B6,选手名单!A:I,7,0) -> 四,五 | I6: yu | J6: 56 | K6: 一颗大白菜 | L6: 75 | N6: summer | Q6: 决赛bo1
B7: 16 | C7: =VLOOKUP(B7,选手名单!A:I,2,0) -> 你也喜欢河马嘛 | D7: =VLOOKUP(B7,选手名单!A:I,6,0) -> 53 | E7: =VLOOKUP(B7,选手名单!A:I,3,0) -> 189497913 | F7: =VLOOKUP(B7,选手名单!A:I,5,0) -> 5300 | G7: =VLOOKUP(B7,选手名单!A:I,7,0) -> 一,二,三,四,五 | I7: 王亚祈 | J7: 55 | K7: 龙城林子 | L7: 55 | T7: end
B8: 11 | C8: =VLOOKUP(B8,选手名单!A:I,2,0) -> iceice | D8: =VLOOKUP(B8,选手名单!A:I,6,0) -> 45 | E8: =VLOOKUP(B8,选手名单!A:I,3,0) -> 0 | F8: =VLOOKUP(B8,选手名单!A:I,5,0) -> 5500 | G8: =VLOOKUP(B8,选手名单!A:I,7,0) -> 四,五 | I8: 总分 | J8: =SUM(J3:J7) -> 313 | K8: 总分 | L8: =SUM(L3:L7) -> 333
B9: 2 | C9: =VLOOKUP(B9,选手名单!A:I,2,0) -> 一颗大白菜 | D9: =VLOOKUP(B9,选手名单!A:I,6,0) -> 75 | E9: =VLOOKUP(B9,选手名单!A:I,3,0) -> 186753076 | F9: =VLOOKUP(B9,选手名单!A:I,5,0) -> 7500 | G9: =VLOOKUP(B9,选手名单!A:I,7,0) -> 一,二,三 | I9: summer | K9: end
B10: 13 | C10: =VLOOKUP(B10,选手名单!A:I,2,0) -> 赤夜紫雨 | D10: =VLOOKUP(B10,选手名单!A:I,6,0) -> 89 | E10: =VLOOKUP(B10,选手名单!A:I,3,0) -> 187933845 | F10: =VLOOKUP(B10,选手名单!A:I,5,0) -> 8100 | G10: =VLOOKUP(B10,选手名单!A:I,7,0) -> 一,三 | I10: Summer丶夏 | J10: 68 | K10: end | L10: 58 | N10: 笑败
B11: 1 | C11: =VLOOKUP(B11,选手名单!A:I,2,0) -> 笑败 | D11: =VLOOKUP(B11,选手名单!A:I,6,0) -> 84 | E11: =VLOOKUP(B11,选手名单!A:I,3,0) -> 106964785 | F11: =VLOOKUP(B11,选手名单!A:I,5,0) -> 8330 | G11: =VLOOKUP(B11,选手名单!A:I,7,0) -> 一 | I11: 蜡笔大雪 | J11: 88 | K11: 秋 | L11: 90
B12: 10 | C12: =VLOOKUP(B12,选手名单!A:I,2,0) -> 阿魂呐 | D12: =VLOOKUP(B12,选手名单!A:I,6,0) -> 81 | E12: =VLOOKUP(B12,选手名单!A:I,3,0) -> 138558413 | F12: =VLOOKUP(B12,选手名单!A:I,5,0) -> 7500 | G12: =VLOOKUP(B12,选手名单!A:I,7,0) -> 二 | I12: 子熙 | J12: 55 | K12: iqbs | L12: 77 | N12: 第2组BO1 | Q12: end
B13: 3 | C13: =VLOOKUP(B13,选手名单!A:I,2,0) -> 睡衣大大 | D13: =VLOOKUP(B13,选手名单!A:I,6,0) -> 63 | E13: =VLOOKUP(B13,选手名单!A:I,3,0) -> 104465635 | F13: =VLOOKUP(B13,选手名单!A:I,5,0) -> 6000 | G13: =VLOOKUP(B13,选手名单!A:I,7,0) -> 一,二 | I13: 睡衣大大 | J13: 63 | K13: 雲天河 | L13: 76
B14: 15 | C14: =VLOOKUP(B14,选手名单!A:I,2,0) -> End | D14: =VLOOKUP(B14,选手名单!A:I,6,0) -> 58 | E14: =VLOOKUP(B14,选手名单!A:I,3,0) -> 354618808 | F14: =VLOOKUP(B14,选手名单!A:I,5,0) -> 6000 | G14: =VLOOKUP(B14,选手名单!A:I,7,0) -> 一,五 | I14: 虎 | J14: 69 | K14: 云南红豆汤 | L14: 20 | N14: end
B15: 8 | C15: =VLOOKUP(B15,选手名单!A:I,2,0) -> 。。~ | D15: =VLOOKUP(B15,选手名单!A:I,6,0) -> 50 | E15: =VLOOKUP(B15,选手名单!A:I,3,0) -> 136537289 | F15: =VLOOKUP(B15,选手名单!A:I,5,0) -> 5000 | G15: =VLOOKUP(B15,选手名单!A:I,7,0) -> 一,二,三,四 | I15: 总分 | J15: =SUM(J10:J14) -> 343 | K15: 总分 | L15: =SUM(L10:L14) -> 321
B16: 5 | C16: =VLOOKUP(B16,选手名单!A:I,2,0) -> 蜡笔小雪 | D16: =VLOOKUP(B16,选手名单!A:I,6,0) -> 60 | E16: =VLOOKUP(B16,选手名单!A:I,3,0) -> 154029585 | F16: =VLOOKUP(B16,选手名单!A:I,5,0) -> 6000 | G16: =VLOOKUP(B16,选手名单!A:I,7,0) -> 三
B17: 6 | C17: =VLOOKUP(B17,选手名单!A:I,2,0) -> jose | D17: =VLOOKUP(B17,选手名单!A:I,6,0) -> 59 | E17: =VLOOKUP(B17,选手名单!A:I,3,0) -> 1255409177 | F17: =VLOOKUP(B17,选手名单!A:I,5,0) -> 6200 | G17: =VLOOKUP(B17,选手名单!A:I,7,0) -> 三
B18: 19 | C18: =VLOOKUP(B18,选手名单!A:I,2,0) -> 21 | D18: =VLOOKUP(B18,选手名单!A:I,6,0) -> 75 | E18: =VLOOKUP(B18,选手名单!A:I,3,0) -> 277443592 | F18: =VLOOKUP(B18,选手名单!A:I,5,0) -> 6800 | G18: =VLOOKUP(B18,选手名单!A:I,7,0) -> 一
B19: 12 | C19: =VLOOKUP(B19,选手名单!A:I,2,0) -> 秋 | D19: =VLOOKUP(B19,选手名单!A:I,6,0) -> 90 | E19: =VLOOKUP(B19,选手名单!A:I,3,0) -> 1004877057 | F19: =VLOOKUP(B19,选手名单!A:I,5,0) -> 9000 | G19: =VLOOKUP(B19,选手名单!A:I,7,0) -> 一,二,三,四
B20: 9 | C20: =VLOOKUP(B20,选手名单!A:I,2,0) -> starling | D20: =VLOOKUP(B20,选手名单!A:I,6,0) -> 34 | E20: =VLOOKUP(B20,选手名单!A:I,3,0) -> 400294058 | F20: =VLOOKUP(B20,选手名单!A:I,5,0) -> 4000 | G20: =VLOOKUP(B20,选手名单!A:I,7,0) -> 四,五
B21: 4 | C21: =VLOOKUP(B21,选手名单!A:I,2,0) -> 军 | D21: =VLOOKUP(B21,选手名单!A:I,6,0) -> 45 | E21: =VLOOKUP(B21,选手名单!A:I,3,0) -> 77006306 | F21: =VLOOKUP(B21,选手名单!A:I,5,0) -> 4600 | G21: =VLOOKUP(B21,选手名单!A:I,7,0) -> 三,四

Sheet 0311内战
B1: 接龙序号 | C1: 微信昵称（群） | D1: 战力值 | E1: 数字id | F1: 参考分数 | G1: 擅长位置 | H1: 备注 | N1: 赛程（一晚上解决，突出一个短平快）
C2: =VLOOKUP(B2,选手名单!A:I,2,0) -> #N/A | D2: =VLOOKUP(B2,选手名单!A:I,6,0) -> #N/A | E2: =VLOOKUP(B2,选手名单!A:I,3,0) -> #N/A | F2: =VLOOKUP(B2,选手名单!A:I,5,0) -> #N/A | G2: =VLOOKUP(B2,选手名单!A:I,7,0) -> #N/A | I2: A风Ain-t | K2: BAA酒水范子 | N2: 风Ain-t
B3: 2 | C3: 赤夜紫雨 | D3: 89 | E3: 187933845 | F3: =VLOOKUP(B3,选手名单!A:I,5,0) -> 7500 | G3: =VLOOKUP(B3,选手名单!A:I,7,0) -> 一,二,三 | I3: 风Ain-t | J3: 88 | K3: AA酒水范子 | L3: 87
B4: 24 | C4: 风Ain-t | D4: 88 | E4: 136801289 | F4: =VLOOKUP(B4,选手名单!A:I,5,0) -> 6500 | G4: =VLOOKUP(B4,选手名单!A:I,7,0) -> 二,四,五 | H4: 队长 | I4: 绮怀. | J4: 28 | K4: defencex | L4: 85 | N4: 第1组BO1 | Q4: 风Ain-t
B5: 6 | C5: oksven | D5: 88 | E5: 0 | F5: =VLOOKUP(B5,选手名单!A:I,5,0) -> 6200 | G5: =VLOOKUP(B5,选手名单!A:I,7,0) -> 三 | H5: 队长 | I5: iqbs | J5: 77 | K5: 清欢不渡 | L5: 45
B6: 21 | C6: AA酒水范子 | D6: 87 | E6: 139963294 | F6: =VLOOKUP(B6,选手名单!A:I,5,0) -> 3000 | G6: =VLOOKUP(B6,选手名单!A:I,7,0) -> 三,四,五 | I6: 小牛 | J6: 75 | K6: 睡衣大大 | L6: 63 | N6: 笑败 | Q6: 12胜者BO1
B7: 3 | C7: 大蟑螂 | D7: 87 | E7: 0 | F7: =VLOOKUP(B7,选手名单!A:I,5,0) -> 6000 | G7: =VLOOKUP(B7,选手名单!A:I,7,0) -> 一,二 | I7: ） | J7: 60 | K7: dalinya | L7: 45
B8: 22 | C8: defencex | D8: 85 | E8: 138235055 | F8: =VLOOKUP(B8,选手名单!A:I,5,0) -> 4300 | G8: =VLOOKUP(B8,选手名单!A:I,7,0) -> 二 | I8: 总分 | J8: =SUM(J3:J7) -> 328 | K8: 总分 | L8: =SUM(L3:L7) -> 325
B9: 27 | C9: 笑败 | D9: 84 | E9: 106964785 | F9: =VLOOKUP(B9,选手名单!A:I,5,0) -> 7000 | G9: =VLOOKUP(B9,选手名单!A:I,7,0) -> 一,二,三,四,五 | I9: C笑败 | K9: D柬埔寨fy
B10: 30 | C10: 精品贵公子 | D10: 83 | E10: 0 | F10: =VLOOKUP(B10,选手名单!A:I,5,0) -> 6800 | G10: =VLOOKUP(B10,选手名单!A:I,7,0) -> 一,二,四,五 | I10: 笑败 | J10: 84 | K10: 柬埔寨fy | L10: 68 | N10: AA酒水范子
B11: 26 | C11: 狮子麒麟凤 | D11: 83 | E11: 266088396 | F11: =VLOOKUP(B11,选手名单!A:I,5,0) -> 7500 | G11: =VLOOKUP(B11,选手名单!A:I,7,0) -> 二 | I11: 大蟑螂 | J11: 87 | K11: 日月同错 | L11: 75 | T11: 决赛BO1
B12: 14 | C12: 阿魂呐 | D12: 81 | E12: 138558413 | F12: =VLOOKUP(B12,选手名单!A:I,5,0) -> 4600 | G12: =VLOOKUP(B12,选手名单!A:I,7,0) -> 四,五 | I12: luyaju | J12: 41 | K12: coconut | L12: 64 | N12: 第2组BO1 | Q12: AA酒水范子 | W12: 冠军
B13: 28 | C13: YuuU | D13: 77 | E13: 885588023 | F13: =VLOOKUP(B13,选手名单!A:I,5,0) -> 6400 | G13: =VLOOKUP(B13,选手名单!A:I,7,0) -> 一 | I13: Summer丶夏 | J13: 68 | K13: 洋芋 | L13: 60
B14: 18 | C14: iqbs | D14: 77 | E14: 383560624 | F14: =VLOOKUP(B14,选手名单!A:I,5,0) -> 5500 | G14: =VLOOKUP(B14,选手名单!A:I,7,0) -> 一,四,五 | I14: 龙城林子 | J14: 55 | K14: Funf | L14: 60 | N14: 柬埔寨fy
I15: 总分 | J15: =SUM(J10:J14) -> 335 | K15: 总分 | L15: =SUM(L10:L14) -> 327 | V15: ➡️
B16: 5 | C16: 雲天河 | D16: 76 | E16: 267719332 | F16: =VLOOKUP(B16,选手名单!A:I,5,0) -> 6000 | G16: =VLOOKUP(B16,选手名单!A:I,7,0) -> 三 | I16: E蜡笔小雪 | K16: Foksven
B17: 32 | C17: 小牛 | D17: 75 | E17: 1259908216 | F17: =VLOOKUP(B17,选手名单!A:I,5,0) -> 0 | G17: =VLOOKUP(B17,选手名单!A:I,7,0) -> 二 | I17: 蜡笔小雪 | J17: 60 | K17: oksven | L17: 88 | N17: 蜡笔小雪
B18: 16 | C18: 21 | D18: 75 | E18: 277443592 | F18: =VLOOKUP(B18,选手名单!A:I,5,0) -> 5300 | G18: =VLOOKUP(B18,选手名单!A:I,7,0) -> 一,二,三,四,五 | I18: YuuU | J18: 77 | K18: 阿魂呐 | L18: 81
B19: 11 | C19: 日月同错 | D19: 75 | E19: 168741476 | F19: =VLOOKUP(B19,选手名单!A:I,5,0) -> 5500 | G19: =VLOOKUP(B19,选手名单!A:I,7,0) -> 四,五 | I19: 赤夜紫雨 | J19: 89 | K19: Thomas | L19: 70 | N19: 第3组BO1BO1 | Q19: 蜡笔小雪
B20: 37 | C20: 新宇宙 | D20: 72 | E20: 139625562 | F20: =VLOOKUP(B20,选手名单!A:I,5,0) -> #N/A | G20: =VLOOKUP(B20,选手名单!A:I,7,0) -> #N/A | I20: PP | J20: 45 | K20: 游牧骑兵 | L20: 30
B21: 19 | C21: Thomas | D21: 70 | E21: 214116802 | F21: =VLOOKUP(B21,选手名单!A:I,5,0) -> 6800 | G21: =VLOOKUP(B21,选手名单!A:I,7,0) -> 一 | I21: 熊 | J21: 55 | K21: jose | L21: 59 | N21: 虎 | Q21: 34胜者BO1
B22: 40 | C22: 虎 | D22: 69 | E22: 106521253 | F22: =VLOOKUP(B22,选手名单!A:I,5,0) -> #N/A | G22: =VLOOKUP(B22,选手名单!A:I,7,0) -> #N/A | I22: 总分 | J22: =SUM(J17:J21) -> 326 | K22: 总分 | L22: =SUM(L17:L21) -> 328 | T22: oksven
B23: 23 | C23: Summer丶夏 | D23: 68 | E23: 355328125 | F23: =VLOOKUP(B23,选手名单!A:I,5,0) -> 8300 | G23: =VLOOKUP(B23,选手名单!A:I,7,0) -> 一,二 | I23: G虎 | K23: H恕
B24: 9 | C24: 柬埔寨fy | D24: 68 | E24: 122810642 | F24: =VLOOKUP(B24,选手名单!A:I,5,0) -> 4000 | G24: =VLOOKUP(B24,选手名单!A:I,7,0) -> 四,五 | H24: 队长 | I24: 虎 | J24: 69 | K24: 恕 | L24: 50
B25: 10 | C25: coconut | D25: 64 | E25: 206673798 | F25: =VLOOKUP(B25,选手名单!A:I,5,0) -> 7500 | G25: =VLOOKUP(B25,选手名单!A:I,7,0) -> 二 | I25: 精品贵公子 | J25: 83 | K25: 狮子麒麟凤 | L25: 83 | N25: oksven
B26: 13 | C26: 睡衣大大 | D26: 63 | E26: 104465635 | F26: =VLOOKUP(B26,选手名单!A:I,5,0) -> 8100 | G26: =VLOOKUP(B26,选手名单!A:I,7,0) -> 一,三 | I26: 新宇宙 | J26: 72 | K26: 21 | L26: 75
B27: 34 | C27: 洋芋 | D27: 60 | E27: 255882400 | F27: =VLOOKUP(B27,选手名单!A:I,5,0) -> 8600 | G27: =VLOOKUP(B27,选手名单!A:I,7,0) -> 一,三 | I27: 王亚祈 | J27: 55 | K27: 雲天河 | L27: 76 | N27: 第4组BO1BO1 | Q27: oksven
B28: 29 | C28: 蜡笔小雪 | D28: 60 | E28: 154029585 | F28: =VLOOKUP(B28,选手名单!A:I,5,0) -> 5000 | G28: =VLOOKUP(B28,选手名单!A:I,7,0) -> 一,三 | H28: 队长 | I28: Vamoose | J28: 55 | K28: 云南红豆汤 | L28: 20
B29: 25 | C29: ） | D29: 60 | E29: 334481697 | F29: =VLOOKUP(B29,选手名单!A:I,5,0) -> 7700 | G29: =VLOOKUP(B29,选手名单!A:I,7,0) -> 四,五,三 | I29: 总分 | J29: =SUM(J24:J28) -> 334 | K29: 总分 | L29: =SUM(L24:L28) -> 304 | N29: F
B30: 17 | C30: Funf | D30: 60 | E30: 0 | F30: =VLOOKUP(B30,选手名单!A:I,5,0) -> 4000 | G30: =VLOOKUP(B30,选手名单!A:I,7,0) -> 一,二,三,四,五
B31: 15 | C31: jose | D31: 59 | E31: 1255409177 | F31: =VLOOKUP(B31,选手名单!A:I,5,0) -> 6000 | G31: =VLOOKUP(B31,选手名单!A:I,7,0) -> 一,五
B32: 41 | C32: 熊 | D32: 55 | E32: 223646770 | F32: =VLOOKUP(B32,选手名单!A:I,5,0) -> #N/A | G32: =VLOOKUP(B32,选手名单!A:I,7,0) -> #N/A
B33: 12 | C33: Vamoose | D33: 55 | E33: 242739321 | F33: =VLOOKUP(B33,选手名单!A:I,5,0) -> 9000 | G33: =VLOOKUP(B33,选手名单!A:I,7,0) -> 一,二,三,四
B34: 8 | C34: 王亚祈 | D34: 55 | E34: 417868870 | F34: =VLOOKUP(B34,选手名单!A:I,5,0) -> 5000 | G34: =VLOOKUP(B34,选手名单!A:I,7,0) -> 一,二,三,四
B35: 7 | C35: 龙城林子 | D35: 55 | E35: 117252110 | F35: =VLOOKUP(B35,选手名单!A:I,5,0) -> 9000 | G35: =VLOOKUP(B35,选手名单!A:I,7,0) -> 二
B36: 39 | C36: dalinya | D36: 45 | E36: 141166215 | F36: =VLOOKUP(B36,选手名单!A:I,5,0) -> #N/A | G36: =VLOOKUP(B36,选手名单!A:I,7,0) -> #N/A
B37: 38 | C37: 清欢不渡 | D37: 45 | E37: 1252995584 | F37: =VLOOKUP(B37,选手名单!A:I,5,0) -> #N/A | G37: =VLOOKUP(B37,选手名单!A:I,7,0) -> #N/A
B38: 20 | C38: PP | D38: 45 | E38: 320479234 | F38: =VLOOKUP(B38,选手名单!A:I,5,0) -> 3400 | G38: =VLOOKUP(B38,选手名单!A:I,7,0) -> 四,五
B39: 33 | C39: luyaju | D39: 41 | E39: 228914641 | F39: =VLOOKUP(B39,选手名单!A:I,5,0) -> 5000 | G39: =VLOOKUP(B39,选手名单!A:I,7,0) -> 一,二
B40: 35 | C40: 游牧骑兵 | D40: 30 | E40: 351772086 | F40: =VLOOKUP(B40,选手名单!A:I,5,0) -> 5800 | G40: =VLOOKUP(B40,选手名单!A:I,7,0) -> 三,四
...

Sheet 0306内战
B1: 接龙序号 | C1: 微信昵称（群） | D1: 战力值 | E1: 数字id | F1: 参考分数 | G1: 擅长位置 | H1: 备注 | N1: 赛程（一晚上解决，突出一个短平快）
B2: 6 | C2: 兆焱 | D2: 90 | E2: 0 | F2: =VLOOKUP(B2,选手名单!A:I,5,0) -> 6200 | G2: =VLOOKUP(B2,选手名单!A:I,7,0) -> 三 | I2: A | K2: B | N2: A
B3: 14 | C3: 秋 | D3: 90 | E3: 1004877057 | F3: =VLOOKUP(B3,选手名单!A:I,5,0) -> 4600 | G3: =VLOOKUP(B3,选手名单!A:I,7,0) -> 四,五 | I3: 荼霏 | J3: 75 | K3: Summer丶夏 | L3: 68
B4: 22 | C4: 风Ain-t | D4: 88 | E4: 136801289 | F4: =VLOOKUP(B4,选手名单!A:I,5,0) -> 4300 | G4: =VLOOKUP(B4,选手名单!A:I,7,0) -> 二 | I4: 秋 | J4: 90 | K4: iqbs | L4: 77 | Q4: A
B5: 23 | C5: Z | D5: 87 | E5: 0 | F5: =VLOOKUP(B5,选手名单!A:I,5,0) -> 8300 | G5: =VLOOKUP(B5,选手名单!A:I,7,0) -> 一,二 | I5: 熊 | J5: 55 | K5: Z | L5: 87
B6: 12 | C6: 精品贵公子 | D6: 83 | E6: 0 | F6: =VLOOKUP(B6,选手名单!A:I,5,0) -> 9000 | G6: =VLOOKUP(B6,选手名单!A:I,7,0) -> 一,二,三,四 | I6: 阿魂呐 | J6: 81 | K6: 小牛 | L6: 75 | N6: C
B7: 15 | C7: 阿鱼 | D7: 82 | E7: 137306952 | F7: =VLOOKUP(B7,选手名单!A:I,5,0) -> 6000 | G7: =VLOOKUP(B7,选手名单!A:I,7,0) -> 一,五 | I7: 授法 | J7: 44 | K7: 哞哞 | L7: 65
B8: 10 | C8: 阿魂呐 | D8: 81 | E8: 138558413 | F8: =VLOOKUP(B8,选手名单!A:I,5,0) -> 7500 | G8: =VLOOKUP(B8,选手名单!A:I,7,0) -> 二 | I8: 总分 | J8: =SUM(J3:J7) -> 345 | K8: 总分 | L8: =SUM(L3:L7) -> 372 | T8: B
B9: 21 | C9: iqbs | D9: 77 | E9: 383560624 | F9: =VLOOKUP(B9,选手名单!A:I,5,0) -> 3000 | G9: =VLOOKUP(B9,选手名单!A:I,7,0) -> 三,四,五 | I9: C | K9: D | N9: B
B10: 7 | C10: 雲天河 | D10: 76 | E10: 267719332 | F10: =VLOOKUP(B10,选手名单!A:I,5,0) -> 9000 | G10: =VLOOKUP(B10,选手名单!A:I,7,0) -> 二 | I10: 蜡笔小雪 | J10: 60 | K10: ArianaW | L10: 50
B11: 26 | C11: 黑色柳丁 | D11: 76 | E11: 457383175 | F11: =VLOOKUP(B11,选手名单!A:I,5,0) -> 7500 | G11: =VLOOKUP(B11,选手名单!A:I,7,0) -> 二 | I11: 风Ain-t | J11: 88 | K11: 雲天河 | L11: 76 | Q11: B
B12: 8 | C12: 荼霏 | D12: 75 | E12: 137852652 | F12: =VLOOKUP(B12,选手名单!A:I,5,0) -> 5000 | G12: =VLOOKUP(B12,选手名单!A:I,7,0) -> 一,二,三,四 | I12: 黑色柳丁 | J12: 76 | K12: 阿鱼 | L12: 82 | W12: 🏆
B13: 16 | C13: 21 | D13: 75 | E13: 277443592 | F13: =VLOOKUP(B13,选手名单!A:I,5,0) -> 5300 | G13: =VLOOKUP(B13,选手名单!A:I,7,0) -> 一,二,三,四,五 | I13: End | J13: 58 | K13: jose | L13: 59 | N13: D | W13: 冠军B | X13: Summer丶夏
B14: 27 | C14: 小牛 | D14: 75 | E14: 1259908216 | F14: =VLOOKUP(B14,选手名单!A:I,5,0) -> 7000 | G14: =VLOOKUP(B14,选手名单!A:I,7,0) -> 一,二,三,四,五 | I14: 爱喝可乐的帅哥！ | J14: 42 | K14: 玖黎 | L14: 52 | X14: iqbs
B15: 25 | C15: 车长老 | D15: 72 | E15: 299025900 | F15: =VLOOKUP(B15,选手名单!A:I,5,0) -> 7700 | G15: =VLOOKUP(B15,选手名单!A:I,7,0) -> 四,五,三 | I15: 总分 | J15: =SUM(J10:J13) -> 282 | K15: 总分 | L15: =SUM(L10:L14) -> 319 | X15: Z
B16: 1 | C16: Summer丶夏 | D16: 68 | E16: 355328125 | F16: =VLOOKUP(B16,选手名单!A:I,5,0) -> 8330 | G16: =VLOOKUP(B16,选手名单!A:I,7,0) -> 一 | I16: E | K16: F | N16: E | X16: 小牛
B17: 20 | C17: 哞哞 | D17: 65 | E17: 235611786 | F17: =VLOOKUP(B17,选手名单!A:I,5,0) -> 3400 | G17: =VLOOKUP(B17,选手名单!A:I,7,0) -> 四,五 | I17: starling | J17: 34 | K17: 绮怀. | L17: 28 | X17: 哞哞
B18: 11 | C18: 洋芋 | D18: 60 | E18: 255882400 | F18: =VLOOKUP(B18,选手名单!A:I,5,0) -> 5500 | G18: =VLOOKUP(B18,选手名单!A:I,7,0) -> 四,五 | I18: 风 | J18: 50 | K18: 车长老 | L18: 72 | Q18: E
B19: 13 | C19: 蜡笔小雪 | D19: 60 | E19: 154029585 | F19: =VLOOKUP(B19,选手名单!A:I,5,0) -> 8100 | G19: =VLOOKUP(B19,选手名单!A:I,7,0) -> 一,三 | I19: 兆焱 | J19: 90 | K19: 21 | L19: 75
B20: 17 | C20: 温酒 | D20: 60 | E20: 117970934 | F20: =VLOOKUP(B20,选手名单!A:I,5,0) -> 4000 | G20: =VLOOKUP(B20,选手名单!A:I,7,0) -> 一,二,三,四,五 | I20: 精品贵公子 | J20: 83 | K20: PP | L20: 45 | N20: F
B21: 29 | C21: jose | D21: 59 | E21: 1255409177 | F21: =VLOOKUP(B21,选手名单!A:I,5,0) -> 5000 | G21: =VLOOKUP(B21,选手名单!A:I,7,0) -> 一,三 | I21: 温酒 | J21: 60 | K21: 洋芋 | L21: 60
B22: 19 | C22: End | D22: 58 | E22: 354618808 | F22: =VLOOKUP(B22,选手名单!A:I,5,0) -> 6800 | G22: =VLOOKUP(B22,选手名单!A:I,7,0) -> 一 | I22: 总分 | J22: =SUM(J17:J21) -> 317 | K22: 总分 | L22: =SUM(L17:L21) -> 280 | T22: E
B23: 28 | C23: 熊 | D23: 55 | E23: 223646770 | F23: =VLOOKUP(B23,选手名单!A:I,5,0) -> 6400 | G23: =VLOOKUP(B23,选手名单!A:I,7,0) -> 一
B24: 9 | C24: 玖黎 | D24: 52 | E24: 208333479 | F24: =VLOOKUP(B24,选手名单!A:I,5,0) -> 4000 | G24: =VLOOKUP(B24,选手名单!A:I,7,0) -> 四,五
B25: 2 | C25: ArianaW | D25: 50 | E25: 454030900 | F25: =VLOOKUP(B25,选手名单!A:I,5,0) -> 7500 | G25: =VLOOKUP(B25,选手名单!A:I,7,0) -> 一,二,三 | Q25: C
B26: 24 | C26: 风 | D26: 50 | E26: 178988576 | F26: =VLOOKUP(B26,选手名单!A:I,5,0) -> 6500 | G26: =VLOOKUP(B26,选手名单!A:I,7,0) -> 二,四,五
B27: 30 | C27: PP | D27: 45 | E27: 320479234 | F27: =VLOOKUP(B27,选手名单!A:I,5,0) -> 6800 | G27: =VLOOKUP(B27,选手名单!A:I,7,0) -> 一,二,四,五
B28: 18 | C28: 授法 | D28: 44 | E28: 370449300 | F28: =VLOOKUP(B28,选手名单!A:I,5,0) -> 5500 | G28: =VLOOKUP(B28,选手名单!A:I,7,0) -> 一,四,五 | Q28: 败者骰子秽土转败者
B29: 32 | C29: 爱喝可乐的帅哥！ | D29: 42 | E29: 101126670 | F29: =VLOOKUP(B29,选手名单!A:I,5,0) -> 0 | G29: =VLOOKUP(B29,选手名单!A:I,7,0) -> 二
B30: 5 | C30: starling | D30: 34 | E30: 400294058 | F30: =VLOOKUP(B30,选手名单!A:I,5,0) -> 6000 | G30: =VLOOKUP(B30,选手名单!A:I,7,0) -> 三 | T30: 老五老六
B31: 31 | C31: 游牧骑兵 | D31: 30 | E31: 351772086 | F31: =VLOOKUP(B31,选手名单!A:I,5,0) -> 4000 | G31: =VLOOKUP(B31,选手名单!A:I,7,0) -> 二,四,五
B32: 3 | C32: 绮怀. | D32: 28 | E32: 283980530 | F32: =VLOOKUP(B32,选手名单!A:I,5,0) -> 6000 | G32: =VLOOKUP(B32,选手名单!A:I,7,0) -> 一,二 | Q32: 败者骰子秽土转败者
B33: 4 | C33: 云南红豆汤 | D33: 20 | E33: 110837873 | F33: =VLOOKUP(B33,选手名单!A:I,5,0) -> 4600 | G33: =VLOOKUP(B33,选手名单!A:I,7,0) -> 三,四

Sheet 0304内战
B1: 接龙序号 | C1: 微信昵称（群） | D1: 战力值 | E1: 数字id | F1: 参考分数 | G1: 擅长位置 | H1: 备注 | N1: 赛程（一晚上解决，突出一个短平快）
B2: 1 | C2: 绮怀. | D2: 28 | E2: =VLOOKUP(B2,选手名单!A:I,3,0) -> 106964785 | F2: =VLOOKUP(B2,选手名单!A:I,5,0) -> 8330 | G2: =VLOOKUP(B2,选手名单!A:I,7,0) -> 一 | I2: A 绮怀. | K2: B 忧郁的苹果君 | N2: A
B3: 15 | C3: 忧郁的苹果君 | D3: 30 | E3: =VLOOKUP(B3,选手名单!A:I,3,0) -> 354618808 | F3: =VLOOKUP(B3,选手名单!A:I,5,0) -> 6000 | G3: =VLOOKUP(B3,选手名单!A:I,7,0) -> 一,五 | I3: 绮怀. | J3: 28 | K3: 忧郁的苹果君 | L3: 30
B4: 24 | C4: 龙城林子 | D4: 41 | E4: =VLOOKUP(B4,选手名单!A:I,3,0) -> 267719332 | F4: =VLOOKUP(B4,选手名单!A:I,5,0) -> 6500 | G4: =VLOOKUP(B4,选手名单!A:I,7,0) -> 二,四,五 | I4: 风 | J4: 88 | K4: 所念皆星河 | L4: 85 | Q4: D
B5: 8 | C5: 清欢不渡 | D5: 45 | E5: =VLOOKUP(B5,选手名单!A:I,3,0) -> 136537289 | F5: =VLOOKUP(B5,选手名单!A:I,5,0) -> 5000 | G5: =VLOOKUP(B5,选手名单!A:I,7,0) -> 一,二,三,四 | I5: Z | J5: 87 | K5: sdy | L5: 78
B6: 17 | C6: PP | D6: 45 | E6: =VLOOKUP(B6,选手名单!A:I,3,0) -> 158643480 | F6: =VLOOKUP(B6,选手名单!A:I,5,0) -> 4000 | G6: =VLOOKUP(B6,选手名单!A:I,7,0) -> 一,二,三,四,五 | I6: yu | J6: 56 | K6: 中专肄业 | L6: 65 | N6: D
B7: 30 | C7: 恕 | D7: 45 | E7: =VLOOKUP(B7,选手名单!A:I,3,0) -> 137852652 | F7: =VLOOKUP(B7,选手名单!A:I,5,0) -> 6800 | G7: =VLOOKUP(B7,选手名单!A:I,7,0) -> 一,二,四,五 | I7: 玖黎 | J7: 52 | K7: 余生只有 | L7: 65
B8: 4 | C8: 熊 | D8: 50 | E8: =VLOOKUP(B8,选手名单!A:I,3,0) -> 77006306 | F8: =VLOOKUP(B8,选手名单!A:I,5,0) -> 4600 | G8: =VLOOKUP(B8,选手名单!A:I,7,0) -> 三,四 | I8: 总分 | J8: =SUM(J3:J7) -> 311 | K8: 总分 | L8: =SUM(L3:L7) -> 323 | T8: F
B9: 23 | C9: ArianaW | D9: 50 | E9: =VLOOKUP(B9,选手名单!A:I,3,0) -> 417861014 | F9: =VLOOKUP(B9,选手名单!A:I,5,0) -> 8300 | G9: =VLOOKUP(B9,选手名单!A:I,7,0) -> 一,二 | I9: C 龙城林子 | K9: D 清欢不渡 | N9: B
B10: 18 | C10: 玖黎 | D10: 52 | E10: =VLOOKUP(B10,选手名单!A:I,3,0) -> 417868870 | F10: =VLOOKUP(B10,选手名单!A:I,5,0) -> 5500 | G10: =VLOOKUP(B10,选手名单!A:I,7,0) -> 一,四,五 | I10: 龙城林子 | J10: 41 | K10: 清欢不渡 | L10: 45
B11: 29 | C11: LuYu | D11: 52 | E11: =VLOOKUP(B11,选手名单!A:I,3,0) -> 178988576 | F11: =VLOOKUP(B11,选手名单!A:I,5,0) -> 5000 | G11: =VLOOKUP(B11,选手名单!A:I,7,0) -> 一,三 | I11: zealot4u | J11: 90 | K11: 雲天河 | L11: 76 | Q11: F
B12: 26 | C12: yu | D12: 56 | E12: =VLOOKUP(B12,选手名单!A:I,3,0) -> 1259908216 | F12: =VLOOKUP(B12,选手名单!A:I,5,0) -> 7500 | G12: =VLOOKUP(B12,选手名单!A:I,7,0) -> 二 | I12: 一颗大白菜 | J12: 75 | K12: End | L12: 58 | W12: 🏆
B13: 19 | C13: End | D13: 58 | E13: =VLOOKUP(B13,选手名单!A:I,3,0) -> 277443592 | F13: =VLOOKUP(B13,选手名单!A:I,5,0) -> 6800 | G13: =VLOOKUP(B13,选手名单!A:I,7,0) -> 一 | I13: ArianaW | J13: 50 | K13: Summer丶夏 | L13: 68 | N13: F | W13: F | X13: 恕
B14: 28 | C14: jose | D14: 59 | E14: =VLOOKUP(B14,选手名单!A:I,3,0) -> 323934704 | F14: =VLOOKUP(B14,选手名单!A:I,5,0) -> 6400 | G14: =VLOOKUP(B14,选手名单!A:I,7,0) -> 一 | I14: 熊 | J14: 50 | K14: BLY | L14: 72 | X14: 秋
B15: 2 | C15: 睡衣大大 | D15: 60 | E15: =VLOOKUP(B15,选手名单!A:I,3,0) -> 186753076 | F15: =VLOOKUP(B15,选手名单!A:I,5,0) -> 7500 | G15: =VLOOKUP(B15,选手名单!A:I,7,0) -> 一,二,三 | I15: 总分 | J15: =SUM(J10:J13) -> 256 | K15: 总分 | L15: =SUM(L10:L14) -> 319 | X15: 21
B16: 9 | C16: 蜡笔小雪 | D16: 60 | E16: =VLOOKUP(B16,选手名单!A:I,3,0) -> 400294058 | F16: =VLOOKUP(B16,选手名单!A:I,5,0) -> 4000 | G16: =VLOOKUP(B16,选手名单!A:I,7,0) -> 四,五 | I16: E PP | K16: F 恕 | N16: C | X16: jose
B17: 10 | C17: 哞哞 | D17: 65 | E17: =VLOOKUP(B17,选手名单!A:I,3,0) -> 138558413 | F17: =VLOOKUP(B17,选手名单!A:I,5,0) -> 7500 | G17: =VLOOKUP(B17,选手名单!A:I,7,0) -> 二 | I17: PP | J17: 45 | K17: 恕 | L17: 45 | X17: 睡衣大大
B18: 21 | C18: 余生只有 | D18: 65 | E18: =VLOOKUP(B18,选手名单!A:I,3,0) -> 351772086 | F18: =VLOOKUP(B18,选手名单!A:I,5,0) -> 3000 | G18: =VLOOKUP(B18,选手名单!A:I,7,0) -> 三,四,五 | I18: 蜡笔小雪 | J18: 60 | K18: 秋 | L18: 88 | Q18: CE胜者
B19: 22 | C19: 中专肄业 | D19: 65 | E19: =VLOOKUP(B19,选手名单!A:I,3,0) -> 235611786 | F19: =VLOOKUP(B19,选手名单!A:I,5,0) -> 4300 | G19: =VLOOKUP(B19,选手名单!A:I,7,0) -> 二 | I19: 赤夜紫雨 | J19: 89 | K19: 21 | L19: 73
B20: 5 | C20: Summer丶夏 | D20: 68 | E20: =VLOOKUP(B20,选手名单!A:I,3,0) -> 154029585 | F20: =VLOOKUP(B20,选手名单!A:I,5,0) -> 6000 | G20: =VLOOKUP(B20,选手名单!A:I,7,0) -> 三 | I20: 哞哞 | J20: 65 | K20: jose | L20: 59 | N20: E
B21: 27 | C21: BLY | D21: 72 | E21: =VLOOKUP(B21,选手名单!A:I,3,0) -> 885588023 | F21: =VLOOKUP(B21,选手名单!A:I,5,0) -> 7000 | G21: =VLOOKUP(B21,选手名单!A:I,7,0) -> 一,二,三,四,五 | I21: LuYu | J21: 52 | K21: 睡衣大大 | L21: 60
B22: 14 | C22: 21 | D22: 73 | E22: =VLOOKUP(B22,选手名单!A:I,3,0) -> 228914641 | F22: =VLOOKUP(B22,选手名单!A:I,5,0) -> 4600 | G22: =VLOOKUP(B22,选手名单!A:I,7,0) -> 四,五 | I22: 总分 | J22: =SUM(J17:J21) -> 311 | K22: 总分 | L22: =SUM(L17:L21) -> 325 | T22: W2
B23: 25 | C23: 一颗大白菜 | D23: 75 | E23: =VLOOKUP(B23,选手名单!A:I,3,0) -> 383560624 | F23: =VLOOKUP(B23,选手名单!A:I,5,0) -> 7700 | G23: =VLOOKUP(B23,选手名单!A:I,7,0) -> 四,五,三
B24: 3 | C24: 雲天河 | D24: 76 | E24: =VLOOKUP(B24,选手名单!A:I,3,0) -> 104465635 | F24: =VLOOKUP(B24,选手名单!A:I,5,0) -> 6000 | G24: =VLOOKUP(B24,选手名单!A:I,7,0) -> 一,二
B25: 20 | C25: sdy | D25: 78 | E25: =VLOOKUP(B25,选手名单!A:I,3,0) -> 168661508 | F25: =VLOOKUP(B25,选手名单!A:I,5,0) -> 3400 | G25: =VLOOKUP(B25,选手名单!A:I,7,0) -> 四,五 | Q25: 败者骰子秽土转生者
B26: 16 | C26: 所念皆星河 | D26: 85 | E26: =VLOOKUP(B26,选手名单!A:I,3,0) -> 189497913 | F26: =VLOOKUP(B26,选手名单!A:I,5,0) -> 5300 | G26: =VLOOKUP(B26,选手名单!A:I,7,0) -> 一,二,三,四,五
B27: 12 | C27: Z | D27: 87 | E27: =VLOOKUP(B27,选手名单!A:I,3,0) -> 1004877057 | F27: =VLOOKUP(B27,选手名单!A:I,5,0) -> 9000 | G27: =VLOOKUP(B27,选手名单!A:I,7,0) -> 一,二,三,四
B28: 7 | C28: 秋 | D28: 88 | E28: =VLOOKUP(B28,选手名单!A:I,3,0) -> 341670770 | F28: =VLOOKUP(B28,选手名单!A:I,5,0) -> 9000 | G28: =VLOOKUP(B28,选手名单!A:I,7,0) -> 二
B29: 11 | C29: 风 | D29: 88 | E29: =VLOOKUP(B29,选手名单!A:I,3,0) -> 0 | F29: =VLOOKUP(B29,选手名单!A:I,5,0) -> 5500 | G29: =VLOOKUP(B29,选手名单!A:I,7,0) -> 四,五
B30: 13 | C30: 赤夜紫雨 | D30: 89 | E30: =VLOOKUP(B30,选手名单!A:I,3,0) -> 187933845 | F30: =VLOOKUP(B30,选手名单!A:I,5,0) -> 8100 | G30: =VLOOKUP(B30,选手名单!A:I,7,0) -> 一,三
B31: 6 | C31: zealot4u | D31: 90 | E31: =VLOOKUP(B31,选手名单!A:I,3,0) -> 1255409177 | F31: =VLOOKUP(B31,选手名单!A:I,5,0) -> 6200 | G31: =VLOOKUP(B31,选手名单!A:I,7,0) -> 三
B32: 31 | C32: =VLOOKUP(B32,选手名单!A:I,2,0) -> 老K | D32: =VLOOKUP(B32,选手名单!A:I,6,0) -> 40 | E32: =VLOOKUP(B32,选手名单!A:I,3,0) -> 148343069 | F32: =VLOOKUP(B32,选手名单!A:I,5,0) -> 4000 | G32: =VLOOKUP(B32,选手名单!A:I,7,0) -> 二,四,五
B33: 32 | C33: =VLOOKUP(B33,选手名单!A:I,2,0) -> 黑色柳丁 | D33: =VLOOKUP(B33,选手名单!A:I,6,0) -> 76 | E33: =VLOOKUP(B33,选手名单!A:I,3,0) -> 457383175 | F33: =VLOOKUP(B33,选手名单!A:I,5,0) -> 0 | G33: =VLOOKUP(B33,选手名单!A:I,7,0) -> 二
B34: 33 | C34: =VLOOKUP(B34,选手名单!A:I,2,0) -> 杜麦尼 | D34: =VLOOKUP(B34,选手名单!A:I,6,0) -> 50 | E34: =VLOOKUP(B34,选手名单!A:I,3,0) -> 157424993 | F34: =VLOOKUP(B34,选手名单!A:I,5,0) -> 5000 | G34: =VLOOKUP(B34,选手名单!A:I,7,0) -> 一,二
B35: 34 | C35: =VLOOKUP(B35,选手名单!A:I,2,0) -> 精品贵公子 | D35: =VLOOKUP(B35,选手名单!A:I,6,0) -> 83 | E35: =VLOOKUP(B35,选手名单!A:I,3,0) -> 0 | F35: =VLOOKUP(B35,选手名单!A:I,5,0) -> 8600 | G35: =VLOOKUP(B35,选手名单!A:I,7,0) -> 一,三
B36: 35 | C36: =VLOOKUP(B36,选手名单!A:I,2,0) -> 宇文成都 | D36: =VLOOKUP(B36,选手名单!A:I,6,0) -> 55 | E36: =VLOOKUP(B36,选手名单!A:I,3,0) -> 136662507 | F36: =VLOOKUP(B36,选手名单!A:I,5,0) -> 5800 | G36: =VLOOKUP(B36,选手名单!A:I,7,0) -> 三,四
B37: 36 | C37: =VLOOKUP(B37,选手名单!A:I,2,0) -> #N/A | D37: =VLOOKUP(B37,选手名单!A:I,6,0) -> #N/A | E37: =VLOOKUP(B37,选手名单!A:I,3,0) -> #N/A | F37: =VLOOKUP(B37,选手名单!A:I,5,0) -> #N/A | G37: =VLOOKUP(B37,选手名单!A:I,7,0) -> #N/A
B38: 37 | C38: =VLOOKUP(B38,选手名单!A:I,2,0) -> #N/A | D38: =VLOOKUP(B38,选手名单!A:I,6,0) -> #N/A | E38: =VLOOKUP(B38,选手名单!A:I,3,0) -> #N/A | F38: =VLOOKUP(B38,选手名单!A:I,5,0) -> #N/A | G38: =VLOOKUP(B38,选手名单!A:I,7,0) -> #N/A
B39: 38 | C39: =VLOOKUP(B39,选手名单!A:I,2,0) -> #N/A | D39: =VLOOKUP(B39,选手名单!A:I,6,0) -> #N/A | E39: =VLOOKUP(B39,选手名单!A:I,3,0) -> #N/A | F39: =VLOOKUP(B39,选手名单!A:I,5,0) -> #N/A | G39: =VLOOKUP(B39,选手名单!A:I,7,0) -> #N/A
B40: 39 | C40: =VLOOKUP(B40,选手名单!A:I,2,0) -> #N/A | D40: =VLOOKUP(B40,选手名单!A:I,6,0) -> #N/A | E40: =VLOOKUP(B40,选手名单!A:I,3,0) -> #N/A | F40: =VLOOKUP(B40,选手名单!A:I,5,0) -> #N/A | G40: =VLOOKUP(B40,选手名单!A:I,7,0) -> #N/A
...

Sheet 0302内战
B1: 接龙序号 | C1: 微信昵称（群） | D1: 战力值 | E1: 数字id | F1: 参考分数 | G1: 擅长位置 | H1: 备注
C2: =VLOOKUP(B2,选手名单!A:I,2,0) -> #N/A | D2: =VLOOKUP(B2,选手名单!A:I,6,0) -> #N/A | E2: =VLOOKUP(B2,选手名单!A:I,3,0) -> #N/A | F2: =VLOOKUP(B2,选手名单!A:I,5,0) -> #N/A | G2: =VLOOKUP(B2,选手名单!A:I,7,0) -> #N/A | P2: 秋
